Workbook
Name Slicer_סוג_תחנה: #REF!
Name Slicer_מנה_פ: #REF!
Name Slicer_סוג_תחנה1: #REF!
Name Slicer_סטטוס_הפרויקט_על_ציר_הזמן1: #REF!
Name Slicer_לדיווח: #REF!
Name Slicer_סיכון: #REF!
Name Slicer_מנה_פ1: #REF!
Name Slicer_חסם: #REF!
Name Slicer_סטטוס_הפרויקט_על_ציר_הזמן: #REF!
Name Slicer_לטיפול: #REF!
Name Slicer_חסם1: #REF!
Name Slicer_תו_ב: #REF!
Name SlicerCache_Table_1_Col_4: #N/A
Name SlicerCache_Table_1_Col_5: #N/A
Name SlicerCache_Table_1_Col_6: #N/A
Name SlicerCache_Table_1_Col_10: #N/A
Name SlicerCache_Table_1_Col_25: #N/A
Name SlicerCache_Table_1_Col_26: #N/A

Sheet דוח שבועי עדכני
A2: לדיווח | B2: זיהוי | C2: שם הפרויקט | D2: סוג תחנה | E2: מנה"פ | F2: תו"ב | G2: יעד תכנית פיתוח | H2: יעד חשמול מסתמן | I2: סיכון | J2: סטטוס הפרויקט על ציר הזמן | K2: זיהוי2 | L2: פירוט שבועי דוח קודם 7.1 | M2: פירוט שבועי 14.1 | N2: פירוט שבועי 21.1 | O2: פירוט שבועי 28.1 | P2: פירוט שבועי 04.02.26 | Q2: פירוט שבועי 11.02.26 | R2: פירוט שבועי 18.02.26 | S2: פירוט שבועי 25.02.2026 | T2: פירוט שבועי 04/03/2026 | U2: פירוט שבועי 11/03/2026 | V2: פירוט שבועי 18/03/2026 | W2: פירוט שבועי 25/03/2026 | X2: פירוט סיכונים וחסמים עיקריים | Y2: לטיפול | Z2: לטיפול נוסף (במידה ונדרש) | AA2: עמודה1
A3: כן | B3: WBC-064 | C3: רעות - הקמת תחמ"ש פנימית 161/24 ק"ו | D3: הקמה | E3: אוברקוביץ, ענת | F3: סויסה ענת | G3: 46934 | H3: 46934 | J3: קבלת היתר | K3: ="WBS: " & B3 & CHAR(10) & "שם פרויקט: " & C3 & CHAR(10) & "מנה״פ: " & E3 & CHAR(10) & "יעד תכנית פיתוח: " & TEXT(G3,"dd/mm/yyyy") & CHAR(10) & "יעד מסתמן: " & TEXT(H3,"dd/mm/yyyy") -> WBS: WBC-064 שם פרויקט: רעות - הקמת תחמ"ש פנימית 161/24 ק"ו מנה״פ: אוברקוביץ, ענת יעד תכנית פיתוח: 30/06/2028 יעד מסתמן: 30/06/2028 | M3: התקבלה תשובה מהועדה.בשלב השלמת בקרת תכן. החל תהליך חישוף השטח ע"י רשות העתיקות .כריתת עצים הושלמה. הוצאו חסמים של בזק, מקורות עבור דרך הגישה. פועלים להסדרת נושא חיבור מים מול תאגיד מי מודיעין. שטח התארגנות: מאחר שאין אפשרות להסדיר שטחי התארגנות מחוץ לגבולות המגרש, נדרש להתארגן בתוך שטח התחנה - ככל הנראה באזור השנאים ובשטח הנכסי. מצב זה עלול ליצור עיכובים בהמשך, שכן במהלך העבודות יידרש להזיז את המכולות, מה שעשוי להשפיע על עמידה בלוחות הזמנים ובמועדי המסירה. | N3: המשך ביצוע עבודות חפירות ובדיקות בשטח של רשות העתיקות, כולל חפירות ארכיאולוגיות ידניות. תואם פגישה לבחינת לו"ז וסטטוס לתאריך 21.01 כולל עם נציג רט"ג בשל צורך בהשלמת חישוף השטח . המשך טיפול מול מנר"א בנושא תשלום דמי ההקמה וחיבור המים לאתר. השלמת כתב הכמויות 15.01.26. התוכניות נשלחו להדפסה לצורך בדיקת פיקוח בתאריך 19.01. התקבלה אגרת תשלום לבדיקת הכבאות לתחמ"ש רעות בשלב היתר הבניה-השטח מאושר. המשך השלמת תנאי בקרת תכן. | O3: נמשכות עבודות רשות העתיקות בשטח. הערכת זמן נותר כשבועיים. במקביל מתקיים שיח עם רט"ג בנושא חישוף השטח ושמירה על ערכי טבע מוגנים על מנת לקבל אישור מהם. אישור כבאות נשלח לאחר הערות, צפי קבלת אישור אם לא ינתנו הערות נוספות 20.2. נמשך טיפול מול מנר"א בנושא תשלום דמי ההקמה וחיבור המים לאתר. תוכניות הודפסו, נקבעה ישיבת RFT ל 8.2 | P3: לבקשת רשות העתיקות בוצעו מדידות בשטח של כביש הגישה. עבודתם נמשכת גם השבוע. במהלך המדידות התברר כי לא בוצעה כריתה של כלל העצים. המידע הועבר לפיקוח ויש להחזיר את הקבלן לשטח. ב 02.02 התקיימה פגישה בשטח עם רט"ג והסדרה סביבתית בנוגע לערכי טבע הקיימים ודרישותיהם. מנר"א העבירו התייחסות מפורטת בנושא תשלום דמי הקמה וחיבור המים לאתר. מחכים לתגובת התאגיד. תקבע פגישה בנושא. תוכניות מודפסות הועברו לפיקוח. ישיבת RFT תזוז מעט על מנת לאפשר זמן להערות. | Q3: מחכים לאישור מרשות העתיקות לשחרור השטח. לדבריהם ייקח מספר ימים.ולא תהיה מגבלה. קבלן כריתת עצים יחזור לכריתה ופינוי הגזם בשבוע הזה. רט"ג מבקשים מאיתנו לבצע חישוף לכלל השטח ובנוסף לפנות את ערימות החישוף הנמצאות בשטח ולשטח אותן בגובה נמוך על מנת למנוע רקבון של הזרעים. הגזם הנמצא בשטח מפריע למציאת שטח לטובת הקצאת אזור מיועד לשימור קרקע לשימור ולכן נמתין לפינוי הגזם ונקבל החלטה. יעד שבוע הבא. תאגיד המים החזיר תשובה כי אין בסמכותו לפרוץ את הדרך שהציע לחיבור מים ולכן אנו בודקים מול התכנון האם ניתן להעביר את הצנרת לאורך תוואי הכביש המתוכנן בדרך אותה אנו פורצים ומסדרים בכל מקרה. בהתאם תוחזר תשובה לתאגיד ונבקש תיאום תכנון. ישיבת RFT נקבעה ליום חמישי 12.02 | R3: רשות העתיקות - התקבל אישור. יידרשו מספר ימי פיקוח בתחילת עבודות הבנייה. פינוי גזם העצים יתבצע במהלך השבוע. לאחר מכן נבצע חשיבה עם רט"ג ופיקוח למציאת שטח לטובת אחסון הקרקע לשימור. תאגיד המים - נושא חיבור המים לתחמ"ש נמצא בשיח מול התאגיד. הוצע לחבר את השטח לאורך כביש הגישה אותו חח"י פורצת ומסדירה. מחכים לתגובתם. בוצעה ישיבת RFT. לקראת סוף שבוע, הוגדר כי יש להעביר הערות נוספות להתייחסויות עד 16.02 ולאחר מכן סוף שבוע, תחילת שבוע הבא התוכניות ישלחו למכרזים. כביש גישה - היתר הבנייה הוא עבור התחמ"ש וכביש הגישה יחד. עבודה על כביש הגישה היא נתיב קריטי שחייבת להתבצע בשלב הראשון של העבודות כיוון שהמושב אינו מסכים שנעבור בשטחיו לטובת כניסה לשטח. את הסדרת הצומת עם כביש 443 חברת נת"י מבקשת לבצע לאחר שחח"י תשלם. הועברו אליהם תוכניות לטובת קבלת אומדן. בנוסף, נקבעה ישיבה עם יו"ר המושב על מנת לנסות למצוא פתרון נוסף לכניסה דרך השטח שלהם למספר חודשים עד להסדרת הכביש. | S3: פינוי גזם העצים ממשיך השבוע. לאחר מכן נבצע חשיבה עם רט"ג ופיקוח למציאת שטח לטובת אחסון הקרקע לשימור. תאגיד המים - נושא חיבור המים לתחמ"ש נמצא בשיח מול התאגיד. הוצע לחבר את השטח לאורך כביש הגישה אותו חח"י פורצת ומסדירה. נקבעה פגישה ברביעי 26.02 מולם. בוצעה ישיבת RFT. הוגדר כי יש להעביר הערות נוספות להתייחסויות עד 16.02 . נכון להיום מחכים לפיקוח אזרחי להערות. ניתן יעד העברה לרכש עד 05.03. כביש גישה - היתר הבנייה הוא עבור התחמ"ש וכביש הגישה יחד. עבודה על כביש הגישה היא נתיב קריטי שחייבת להתבצע בשלב הראשון של העבודות כיוון שהמושב אינו מסכים שנעבור בשטחיו לטובת כניסה לשטח. את הסדרת הצומת עם כביש 443 חברת נת"י מבקשת לבצע לאחר שחח"י תשלם. הועברו אליהם תוכניות לטובת קבלת אומדן. בנוסף, נקבעה ישיבה עם יו"ר המושב על מנת לנסות למצוא פתרון נוסף לכניסה דרך השטח שלהם למספר חודשים עד להסדרת הכביש.פגישה נוספת מתקיימת ביום חמישי הקרוב (26.02) מול נציגי המושב. | T3: גזם - העבודה לא הסתיימה. נשאר פינוי של מספר ערמות מהשטח. רט"ג - תבוצע חשיבה עם סיום פינוי הגזם למיקום ערמות הקרקע לשימור. תאגיד המים-בוצע זום עם המנכ"ל. העברנו להם חומרים שביקשו במייל מחכים לתגובתם. צומת מכביש 443-מתנהלים מול נת"י, מחכים לבדיקת התוכניות וקבלת אומדן לעבודה. במקביל בוצעה פגישה עם מזכיר האגודה לבחינה נוספת מצידם לכניסה באופן זמני לתחילת העבודות מהכביש הקיים העובר דרך המושב. תשובה סופית תינתן תוך כשבוע. עדיין מחכים לפיקוח אזרחי לאישור תוכניות והערות סוף השבוע יעד אחרון. | U3: גזם - העבודה לא הסתיימה. נשאר פינוי של מספר ערמות מהשטח, עיכוב בשל המלחמה/גשם. רט"ג - תבוצע חשיבה עם סיום פינוי הגזם למיקום ערמות הקרקע לשימור. תאגיד המים-מנכ"ל מי מודיעין העביר היום התייחסות לשתי האפשריות שהועלו בזום המשותף. נדרש לקיים דיון. כמו כן ניתנה התייחסות לכך שנדרש לבצע חישוב חדש לדמי הקמה. הובטח שישלח בימים הקרובים. צומת מכביש 443-מתנהלים מול נת"י, מחכים לבדיקת התוכניות וקבלת אומדן לעבודה. במקביל בוצעה פגישה עם מזכיר מושב כפר רות לבחינה נוספת מצידם לכניסה באופן זמני לתחילת העבודות מהכביש הקיים העובר דרך המושב. ממתינים לתשובתם לקידום הנושא. RFT סופי נדרש לקבל ב 12/03. בוצעה ישיבה לקביעת מיקום חיבור חשמל זמני. יציאות מ"ג - באחריות תכנון להעביר התייחסות לאור בקשתם לשנות כיוונים וכמויות שתוכננו. סוכם כי שינוי בנספח סביבתי יהיה רק לאחר הקמת היתר בנייה. | V3: גזם - העבודה לא הסתיימה. נשאר פינוי של מספר ערמות מהשטח, עיכוב בשל המלחמה/גשם, קק"ל לא מאשרים כניסה. . רט"ג - תבוצע חשיבה עם סיום פינוי הגזם למיקום ערמות הקרקע לשימור. תאגיד המים-מנכ"ל מי מודיעין העביר התייחסות לשתי האפשריות שהועלו בזום (חיבור לאורך כביש הגישה או חיבור בהמצאות הנחה/קידוח בתא שטח שלא בבעלות אף גורם). יישלח מיל למנהל אגף להחלטה. התקבל חישוב חדש לדמי הקמה ללא היטל לחיבור ביוב. צומת מכביש 443-מתנהלים מול נת"י, מחכים לבדיקת התוכניות וקבלת אומדן לעבודה. במקביל בוצעה פגישה עם מזכיר מושב כפר רות לבחינה נוספת מצידם לכניסה באופן זמני לתחילת העבודות מהכביש הקיים העובר דרך המושב. ממתינים לתשובתם הסופית לקידום הנושא. כעיקרון ניתנה הסכמה, מבקשים סידור של דרכים נוספות, תיקבע פגישה מול מזכיר האגודה יחד עם פיקוח בניין בהקדם. RFT סופי נשלח, יש עדיין בקשה לתיקונים מצד בקרת חוזים בוצעה ישיבה לקביעת מיקום חיבור חשמל זמני. יציאות מ"ג - סוכם כי שינוי בנספח סביבתי יהיה רק לאחר קבלת היתר בנייה. | W3: גזם - העבודה לא הסתיימה. נשאר פינוי של מספר ערמות מהשטח, עיכוב בשל המלחמה/גשם, קק"ל לא מאשרים כניסה. . רט"ג - תבוצע חשיבה עם סיום פינוי הגזם למיקום ערמות הקרקע לשימור. תאגיד המים-נסיון לקדם את החלופה של חיבור מים לאורך הכביש. ישנו דין ודברים מול מנר"א ותאגיד המים לגבי סוגיות תשלום. הועברו תוכניות של הכביש לתאגיד המים. צומת מכביש 443-מתנהלים מול נת"י, מחכים לבדיקת התוכניות וקבלת אומדן לעבודה. במקביל בוצעה פגישה עם מזכיר מושב כפר רות לבחינה נוספת מצידם לכניסה באופן זמני לתחילת העבודות מהכביש הקיים העובר דרך המושב. כמו כן, בוצעה פגישה מולם לבחינת עבודות נוספות שמבקשים לבצע במקום פיצוי כספי. כעיקרון ניתנה הסכמה,מחכים לתצ"א/תוכנית מדידה מסודרת לדרכים הנדרשות להסדרה וכן למכתב מסודר עם בקשתם. RFT סופי נשלח, ינדרש לקדם נספח 5 בהקדם. בטיפול מול בוריס. יציאות מ"ג - סוכם כי שינוי בנספח סביבתי יהיה רק לאחר קבלת היתר בנייה. התקבל אישור כיבוי אש ואישור תשתיות עבור ההיתר. | X3: 1. חיבור מים למגרש - בשיח מול התאגיד למציאת פתרון והורדת החסם לאישור נספח סניטרי . 2. שטח התארגנות מצומצם רק בשטח העבודות בלבד. 3. קבלת היתר לפי לו"ז מתוכנן (אישור כיבוי אש, אישור רמ"י, אישור נספח סניטרי). 4. מכרז לבחירת קבלן בשל עיכובים ברכש. 5. עבודות חפירה ודיפון משמעותיות שיכולות להאריך את העבודה. 6. כביש גישה - חסם עיקרי כרגע! לא ניתן להתחיל עבודות בשטח ללא הסדרת דרך גישה. | Y3: חסם לטיפול מנהל מגזר בפיקוח
A4: כן | B4: WBE-158 | C4: ראש העין-הוספת שנאי 521 והרחבת פ"צ 161 | D4: הרחבה | E4: אוברקוביץ, ענת | F4: סויסה ענת | G4: 46111 | H4: 46264 | J4: הרכבה חשמלית | K4: ="WBS: " & B4 & CHAR(10) & "שם פרויקט: " & C4 & CHAR(10) & "מנה״פ: " & E4 & CHAR(10) & "יעד תכנית פיתוח: " & TEXT(G4,"dd/mm/yyyy") & CHAR(10) & "יעד מסתמן: " & TEXT(H4,"dd/mm/yyyy") -> WBS: WBE-158 שם פרויקט: ראש העין-הוספת שנאי 521 והרחבת פ"צ 161 מנה״פ: אוברקוביץ, ענת יעד תכנית פיתוח: 30/03/2026 יעד מסתמן: 30/08/2026 | M4: הגיע מייל מ GE כי צפי להגעת ציוד להרחבת מסדר 161 הינו 03/26. הרכבת תמיכות - בתהליך. שנאי נמצא בתחנה, מלא בשמן. | N4: בוצעה ישיבה מול נציגי GE להבנת לו"ז הפרויקט מבחינתם וסטטוס קבלת ציוד. רוב הציוד מוכן למשלוח, ישנו פרט שנדרש לייצר מחדש ע"פ המייל שהגיע-מחכים להתייחסות למשמעות חלק זה . יש לבחון בהתאם ללו"ז הגעת הציוד את תחילת עבודות המומחה בשטח (אמצע מרץ/לאחר פס 12.4). תתואם ישיבת המשך מול GE. | O4: מתאמים כעת עם כלל הגורמים, כדי שנוכל להתכנס לתחילת העבודות מיד לאחר פסח, בתאריך 12.4, וכן לתת ל‑GE אישור להגעת המומחה במועד זה | P4: מתאמים כעת עם כלל הגורמים, כדי שנוכל להתכנס לתחילת העבודות מיד לאחר פסח, בתאריך 12.4, וכן לתת ל‑GE אישור להגעת המומחה במועד זה | Q4: מתאמים כעת עם כלל הגורמים, כדי שנוכל להתכנס לתחילת העבודות מיד לאחר פסח, בתאריך 12.4, וכן לתת ל‑GE אישור להגעת המומחה במועד זה. ברביעי 11.02 תתקיים ישיבה עם נציג היצרן. נבקש תשובות בנושא לו"ז להגעת הציוד ומוכנותו, לו"ז הגעת מומחים | R4: ממשיכים תיאומים מול GE. נכון ל 16.02 הציוד עדיין לא נשלח לארץ. ממתינים לעדכון. תאריך לתחילת העבודה והגעת מומחה הינו 12.4 נכון לעכשיו. מתבצע תיאום בין העבדות הנדרשות לביצוע ב DCS בין GE ל ABB. מיקי מלכה צפוי לחזור לעבודה באתר החלמתאריך 22.02 לטובת השלמת הרכבת תמיכות מ"ע. לאחר מכן תתואם מול רת"ק העבודה. | S4: ממשיכים תיאומים מול GE. נכון ל 23.02 הציוד עדיין לא נשלח לארץ. ממתינים לעדכון מהרכש. תאריך לתחילת העבודה והגעת מומחה הינו 12.4 נכון לעכשיו. מתבצע תיאום בין העבדות הנדרשות לביצוע ב DCS בין GE ל ABB. השלמת הרכבת תמיכות מ״ע מתעכבת עקב כניסת עבודות דחופות יותר, הדוחקות את הפרויקט בסדר העדיפויות.ניתן לקדם חלק משמעותי מהעבודה כבר כעת, אך בפועל קיים קושי לתאם ולזרז את הצוותים כל עוד המשאבים מופנים לפרויקטים דחופים אחרים. לאחר סיום הרכבת תמיכות יתואם מול רת״ק, כיבוי אש המשך הביצוע. | T4: נמשכו תיאומים השבוע מול GE . נכון ל 2.3.26, הציוד לא נשלח עדיין לארץ. בנוסף, התקבל מייל מGE כי מבקשים לדחות הגעת המומחה לתחילת מאי. הנושא בבחינה מול מגזר ביצוע לקבלת התייחסות בהתאם לסדרי עדיפויות שיוגדרו לפרויקטים. | U4: עדיין מחכים לעדכון מGE ורכש לשליחת ציוד מסדר 161 לארץ. בתיאום מול הרכבה חשמלית ויחידת התחמ"ש סוכם לאשר לGE הגעת מומחה ב 03.05. אך GE הודיעו שכרגע לא יכולים לתת תאריכים מעודכנים ותמיכה עד לסיום המלחמה. תמיכות מ"ג/מ"ע - עבודה מתבצעת השבוע בתקווה לסיים תוך שבוע. | V4: GE העבירו packing list לרכש ב 12/3. בתיאום מול הרכבה חשמלית ויחידת התחמ"ש סוכם לאשר לGE הגעת מומחה ב 03.05. אך GE הודיעו שכרגע לא יכולים לתת תאריכים מעודכנים ותמיכה עד לסיום המלחמה. תמיכות מ"ג/מ"ע - עבודה מתבצעת השבוע בתקווה לסיים תוך שבוע. | W4: ללא שינוי משבוע קודם. מחכים לסטטוס משלוח ציוד מהרכש. הובלה באחריות חח"י. בבדיקה מול המרחב למתי דרושות הזמנות חיבור מ"ג. מחכים לתשובות על מנת האם לקדם פרויקט חיבור מסדר 24 חדש לשנאים קיימים. הפרויקט לא הוכנס לסידור העבודה של הרת"ק. בוצעה התערבות מצד הנהלת החטיבה. | X4: 1. לא ניתן לעמוד ביעד תכנית הפיתוח. הועברה בקשה לשינוי ל 08/26 2. הגעת הציוד לארץ עד מאי 3. סיום עבודות מקדימות למניעת לחץ מיותר עם הגעת המומחה לארץ - האם העבודות יבוצעו ללא מומחה. תידרש בחינה | Y4: חסם לטיפול מנהל מגזר ביצוע | AD4: ="WBS: " & B4 & CHAR(10) & "שם פרויקט: " & D4 & CHAR(10) & "מנה״פ: " & E4 & CHAR(10) & "יעד תכנית פיתוח: " & TEXT(G4,"dd/mm/yyyy") & CHAR(10) & "יעד מסתמן: " & TEXT(H4,"dd/mm/yyyy") -> WBS: WBE-158 שם פרויקט: הרחבה מנה״פ: אוברקוביץ, ענת יעד תכנית פיתוח: 30/03/2026 יעד מסתמן: 30/08/2026
B5: WBE-188 | C5: אור יהודה -התקנת שנאי רביעי 161/24 ק"ו, 50 מגוו"א וסוללת קבלים | D5: הרחבה | E5: אוברקוביץ, ענת | F5: סויסה ענת | G5: 46752 | H5: 46751 | J5: הקפאת תצורה | K5: ="WBS: " & B5 & CHAR(10) & "שם פרויקט: " & C5 & CHAR(10) & "מנה״פ: " & E5 & CHAR(10) & "יעד תכנית פיתוח: " & TEXT(G5,"dd/mm/yyyy") & CHAR(10) & "יעד מסתמן: " & TEXT(H5,"dd/mm/yyyy") -> WBS: WBE-188 שם פרויקט: אור יהודה -התקנת שנאי רביעי 161/24 ק"ו, 50 מגוו"א וסוללת קבלים מנה״פ: אוברקוביץ, ענת יעד תכנית פיתוח: 31/12/2027 יעד מסתמן: 30/12/2027 | M5: נכון לעכשיו, מקדמים התקנת מסדר מ"ג וחיבורו בעזרת שדות מקשרים למסדרי מ"ג קיימים (WBM-10562-ST1) .. המסדר הורכב. הוחלט לקדם בשלב זה את הפרויקט עם ייצור ארונות הגנה של ABB לטובת חשמול ב 06/26 ע"פ החלטת סמנכ"ל שירותי רשת. ארונות הגנה 01/26. תכנון חשמל מפורט 11/25.יש להתארגן להחזרת הרכבה חשמלית לעבודה בתיאום עם יחידת התחמ"ש בסוף ינואר. בוצעה ישיבה לשינוי תכולות ב 24.12.25. הועבר להמשך טיפול גיל חזום. לגבי הפרויקט הספציפי של החלפת השנאי, יעד כרגע לקבלת תכניות אלקטרומכניות 01.26. תתואם ישיבה להתנעת הפרויקט במקביל לישיבת שינוי תכולות כלל הפרויקטים בתחנה זו בתחילת ינואר | N5: תכולות הפרויקטים באור יהודה עודכנו. תתואם בהקדם ישיבת התנעת הפרויקט. | O5: צריך לקבל תיעדוף תכנון לקבלת תכניות מעודכנות וכתב כמויות . מתוכננת ישיבת התנעה בפברואר | P5: פרויקט מקדים (WBM-10562-ST1) בביצוע. מסדר מ"ג נבדק כעת ע"י מדור בדיקות. במקביל מתואמת המשך עבודה מול הרכבה חשמלית ויחידת התחמ"ש. שאר תכולות הפרויקטים עודכנו מול נגה ומול כל הגורמים (תפעול השנאה, תחמ"ש) ומתוכננת ישיבת התנעה במהלך החודש (בתיאום מול תכנון א"מ) להמשך שאר העבודות באשכול הפרויקטים בתחנה. נתנה התייחסות ממגזר תכנון ליעד כתב כמויות 08.2026. | Q5: פרויקט מקדים WBM-10562-ST1, מדור בדיקות סיים. צוות מבדקת תחמ"ש נכנס לעבודה לבדיקות מ"ז על מנת לאתר ליקויים ולהזמין את אפקון להמשך עבודה. הרכבה חשמלית תכנס החל מיום רביעי לעבודה להרכבת ארונות הגנה. עבור המשך העבודות באשכול הפרויקטים, יצאה פנייה מתכנון אלקטרומכני לקבלת סכימת חיבור מעודכנת ובהתאם ועם קבלת תשובות תתואם ישיבת התנעת פרויקט. | R5: פרויקט מקדים WBM-10562-ST1, מדור בדיקות סיים. צוות מבדקת תחמ"ש נכנס לעבודה לבדיקות מ"ז אפקון מוזמנים ב 19.02 לתיקון ליקויים. הרכבה חשמלית נמצאת באתר להרכבת ארונות הגנה. עבור המשך העבודות באשכול הפרויקטים, יצאה פנייה מתכנון אלקטרומכני לקבלת סכימת חיבור מעודכנת ובהתאם ועם קבלת תשובות תתואם ישיבת התנעת פרויקט. | S5: מתבצעות עבודות עבור פרויקט מקדים WBM-10562-ST1. נקבעה ישיבת התנעת פרויקט WBE-188 לתאריך 22.03 | T5: מתבצעות עבודות עבור פרויקט מקדים WBM-10562-ST1. נקבעה ישיבת התנעת פרויקט WBE-188 לתאריך 22.03 | U5: מתבצעות עבודות הרכבה חשמלית ומבדקת תחמ"ש עבור פרויקט מקדים WBM-10562-ST1 (היתה מעט פעילות השבוע בעקבות המלחמה וצורך בבודקים עבור ניידות חירום). נקבעה ישיבת התנעת פרויקט WBE-188 לתאריך 22.03 | V5: מתבצעות עבודות הרכבה חשמלית ומבדקת תחמ"ש עבור פרויקט מקדים WBM-10562-ST1 . על מנת להמשיך בעבודות ובמסירה של ה.חשמלית נדרש שאפקון יגיעו לתיקון ליקויים. הנושא מתעכב בשל סקר סיכונים לא תקין שנשלח ע"י אפקון מה שמונע ממונה בטיחות לאשר את קיום העבודה. מנהל המגזר מעורב. נקבעה ישיבת התנעת לפרויקט WBE-188 לתאריך 22.03 - הישיבה תידחה. תכנון ראשוני עוד לא מוכן. | W5: מתבצעות עבודות הרכבה חשמלית ומבדקת תחמ"ש עבור פרויקט מקדים WBM-10562-ST1 . קבלן חיווט של הרכבה חשמלית עובד בתחנה. תואם מול הרכבה חשמלית תיקון ליקויים אפקון בתאריך 19/4. בודקים של יחידת התחמ"ש יכנסו לעבודה החל מ 12/4. נקבעה ישיבת התנעת לפרויקט WBE-188 לאחר חג הפסח. | X5: עמידה בלו"ז. הגעת ציוד מסדר 161 ק"ו בזמן. | Y5: חסם לטיפול מנהל מגזר תכנון | AD5: ="WBS: " & B5 & CHAR(10) & "שם פרויקט: " & D5 & CHAR(10) & "מנה״פ: " & E5 & CHAR(10) & "יעד תכנית פיתוח: " & TEXT(G5,"dd/mm/yyyy") & CHAR(10) & "יעד מסתמן: " & TEXT(H5,"dd/mm/yyyy") -> WBS: WBE-188 שם פרויקט: הרחבה מנה״פ: אוברקוביץ, ענת יעד תכנית פיתוח: 31/12/2027 יעד מסתמן: 30/12/2027
B6: WBE-196 | C6: "בארות יצחק – הרחבת פ""צ והוספת שנאי חמישי 161/24 ק""ו, 50 מגוו""א וסוללות קבלים." | D6: הרחבה | E6: אוברקוביץ, ענת | F6: סויסה ענת | G6: 46203 | H6: 46537 | J6: תכנון | K6: ="WBS: " & B6 & CHAR(10) & "שם פרויקט: " & C6 & CHAR(10) & "מנה״פ: " & E6 & CHAR(10) & "יעד תכנית פיתוח: " & TEXT(G6,"dd/mm/yyyy") & CHAR(10) & "יעד מסתמן: " & TEXT(H6,"dd/mm/yyyy") -> WBS: WBE-196 שם פרויקט: "בארות יצחק – הרחבת פ""צ והוספת שנאי חמישי 161/24 ק""ו, 50 מגוו""א וסוללות קבלים." מנה״פ: אוברקוביץ, ענת יעד תכנית פיתוח: 30/06/2026 יעד מסתמן: 30/05/2027 | M6: בישיבה שהתקיימה ב 05.01.26 לבחינת תכולות הפרויקטים לבקשת יחידת התחמ"ש בעקבות שינויים צפויים לבקשת המרחב, הוחלט לוותר על הצבת מכולת מ"ג (פרויקט WBM-10726) ולהתקדם עם הוספת השנאי והמכולה בלבד ולתכנן את הניידת כאופציה להוספה במידת הצורך. נדרש לקבל תאריך להוצאת הזמנה לתכנון אזרחי בהקדם. הגנת פ"צ צפויה לתאריך 6.2027. החלפת ההגנה חייבת להתבצע לפני החלפת השנאי החמישי וכן הארכת פ"צ. לא ניתן לעמוד בתאריך יעד תכנית הפיתוח! | N6: לבקשת גיל חזום, לטובת שינוי הפרויקטים בבארות יצחק מחכים להתייחסות מהמחוז לסיכום ישיבה ואישורם הסופי . במקביל מחכים להוצאת הזמנת תכנון אזרחי בהתאם להחלטות שהתקבלו. | O6: יצאה הזמנה לתכנון אזרחי 20.01.26. במקביל מתאמים תכנון מול מ"ע | P6: יש להתייחס לאשכול פרויקטים בתחנה זו.לאחר מספר דיונים עם כל הגורמים, הוסכם כי תכולות הפרויקטים ישתנו. בקשה זו הועברה לנגה לאישור. עקב מורכבות ביצועית הוצעה חלופה של הצבת ניידת במקום מכולה נוספת, המייתרת שינויים בתחנה ומאפשרת מענה זמני עד לשדרוג התחמ"ש. הוסכם כי פרויקט WBM-10726 הוספת מכולת מ"ג וחיבורה לשנאי 524 יבוטל בהתאם להיתכנות הצבת הניידת. יצאה הזמנה לתכנון אזרחי עבור פרויקט WBE-196 (הרחבת פ"צ והוספת שנאי חמישי+מכולת מ"ג). התקבל יעד כתב כמויות מהתכנון 05.2026 | Q6: יש להתייחס לאשכול פרויקטים בתחנה זו.לאחר מספר דיונים עם כל הגורמים, הוסכם כי תכולות הפרויקטים ישתנו. בקשה זו הועברה לנגה לאישור. עקב מורכבות ביצועית הוצעה חלופה של הצבת ניידת במקום מכולה נוספת, המייתרת שינויים בתחנה ומאפשרת מענה זמני עד לשדרוג התחמ"ש. הוסכם כי פרויקט WBM-10726 הוספת מכולת מ"ג וחיבורה לשנאי 524 יבוטל בהתאם להיתכנות הצבת הניידת. יצאה הזמנה לתכנון אזרחי עבור פרויקט WBE-196 (הרחבת פ"צ והוספת שנאי חמישי+מכולת מ"ג). התקבל יעד כתב כמויות מהתכנון 05.2026 | R6: יש להתייחס לאשכול פרויקטים בתחנה זו.לאחר מספר דיונים עם כל הגורמים, הוסכם כי תכולות הפרויקטים ישתנו. בקשה זו הועברה לנגה לאישור. עקב מורכבות ביצועית הוצעה חלופה של הצבת ניידת במקום מכולה נוספת, המייתרת שינויים בתחנה ומאפשרת מענה זמני עד לשדרוג התחמ"ש. הוסכם כי פרויקט WBM-10726 הוספת מכולת מ"ג וחיבורה לשנאי 524 יבוטל בהתאם להיתכנות הצבת הניידת. יצאה הזמנה לתכנון אזרחי עבור פרויקט WBE-196 (הרחבת פ"צ והוספת שנאי חמישי+מכולת מ"ג). התקבל יעד כתב כמויות מהתכנון 05.2026. בבדיקת היתכנות להנפת יסודות טרומיים עבור שדה שנאי | S6: יש להתייחס לאשכול פרויקטים בתחנה זו.לאחר מספר דיונים עם כל הגורמים, הוסכם כי תכולות הפרויקטים ישתנו. בקשה זו הועברה לנגה לאישור. עקב מורכבות ביצועית הוצעה חלופה של הצבת ניידת במקום מכולה נוספת, המייתרת שינויים בתחנה ומאפשרת מענה זמני עד לשדרוג התחמ"ש. הוסכם כי פרויקט WBM-10726 הוספת מכולת מ"ג וחיבורה לשנאי 524 יבוטל בהתאם להיתכנות הצבת הניידת. נקבעה ישיבה מול מיקי אזוט וחטיבת רשת לדיוק צרכים בפנייה לנגה לתאריך 7.03. יצאה הזמנה לתכנון אזרחי עבור פרויקט WBE-196 (הרחבת פ"צ והוספת שנאי חמישי+מכולת מ"ג). התקבל יעד כתב כמויות מהתכנון 05.2026. בבדיקת היתכנות להנפת יסודות טרומיים עבור שדה שנאי | T6: יש להתייחס לאשכול פרויקטים בתחנה זו.לאחר מספר דיונים עם כל הגורמים, הוסכם כי תכולות הפרויקטים ישתנו. בקשה זו הועברה לנגה לאישור. עקב מורכבות ביצועית הוצעה חלופה של הצבת ניידת במקום מכולה נוספת, המייתרת שינויים בתחנה ומאפשרת מענה זמני עד לשדרוג התחמ"ש. הוסכם כי פרויקט WBM-10726 הוספת מכולת מ"ג וחיבורה לשנאי 524 יבוטל בהתאם להיתכנות הצבת הניידת. נקבעה ישיבה מול מיקי אזוט וחטיבת רשת לדיוק צרכים בפנייה לנגה לתאריך 7.03. יצאה הזמנה לתכנון אזרחי עבור פרויקט WBE-196 (הרחבת פ"צ והוספת שנאי חמישי+מכולת מ"ג). התקבל יעד כתב כמויות מהתכנון 05.2026. בבדיקת היתכנות להנפת יסודות טרומיים עבור שדה שנאי . | U6: בוצעה ישיבה היום מול מרחב איילון לטובת בחינת הפרויקטים המתוכננים בתחנה זו. במקביל מקודם פרויקט WBE-196 (הרחבת פ"צ והוספת שנאי חמישי+מכולת מ"ג). הפרויקט נמצא בשלב תכנון אזרחי. סוכם לאחר בחינה מול צמ"ן/יחידת התחמ"ש/פיקוח כי ניתן להתקדם עם תכנון יסודות טרומיים עבור שדה שנאי. | V6: פרויקט WBE-196 (הרחבת פ"צ והוספת שנאי חמישי+מכולת מ"ג): נמצא בשלב תכנון אזרחי. במקביל מתקיימות ישיבות מול חטיבת רשת להגדרת תכולות וצרכים בתחנה זו. יציאות מ"ג - קודמו חפירות גישוש וקידוחי נסיון בתחנה באזור המערבי לטובת המחוז | W6: פרויקט WBE-196 (הרחבת פ"צ והוספת שנאי חמישי+מכולת מ"ג): נמצא בשלב תכנון אזרחי. במקביל מתקיימות ישיבות מול חטיבת רשת להגדרת תכולות וצרכים בתחנה זו. יציאות מ"ג - קודמו חפירות גישוש וקידוחי נסיון בתחנה באזור המערבי לטובת המחוז | X6: 1. לא ניתן לעמוד בתאריך יעד תכנית הפיתוח. הועברה בקשה לשינוי. 2. עמידה בלו"ז הפצת כתב כמויות. 3. אישור נגה ושינוי תכולות הפרויקטים | Y6: חסם לטיפול מנהל מגזר תכנון | AD6: ="WBS: " & B6 & CHAR(10) & "שם פרויקט: " & D6 & CHAR(10) & "מנה״פ: " & E6 & CHAR(10) & "יעד תכנית פיתוח: " & TEXT(G6,"dd/mm/yyyy") & CHAR(10) & "יעד מסתמן: " & TEXT(H6,"dd/mm/yyyy") -> WBS: WBE-196 שם פרויקט: הרחבה מנה״פ: אוברקוביץ, ענת יעד תכנית פיתוח: 30/06/2026 יעד מסתמן: 30/05/2027
B7: WBE-125 | C7: תמנע-רב-שלבי,שדרוג מסדר 161 ק"ו מע' עזר | D7: הרחבה | E7: אוחייון, איתן | F7: בסיל כהן יפעת | G7: 46630 | H7: 46660 | J7: עבודה אזרחית | K7: ="WBS: " & B7 & CHAR(10) & "שם פרויקט: " & C7 & CHAR(10) & "מנה״פ: " & E7 & CHAR(10) & "יעד תכנית פיתוח: " & TEXT(G7,"dd/mm/yyyy") & CHAR(10) & "יעד מסתמן: " & TEXT(H7,"dd/mm/yyyy") -> WBS: WBE-125 שם פרויקט: תמנע-רב-שלבי,שדרוג מסדר 161 ק"ו מע' עזר מנה״פ: אוחייון, איתן יעד תכנית פיתוח: 31/08/2027 יעד מסתמן: 30/09/2027 | M7: קבלן יצא מהשטח, בוצעה ישיבת התנעה עבור השלמות שלב א', שלב ב' (מבנה) והוספת שנאי WBE200 | N7: קבלן יצא מהשטח, בוצעה ישיבת התנעה עבור השלמות שלב א', שלב ב' (מבנה) והוספת שנאי WBE200 נדרש RFT עבור תכולה מאוחדת WBE-125 שלב א', שלב ב' וחומה עד 31/3/2026 | O7: קבלן יצא מהשטח, בוצעה ישיבת התנעה עבור השלמות שלב א', שלב ב' (מבנה) והוספת שנאי WBE200 נדרש RFT עבור תכולה מאוחדת WBE-125 שלב א', שלב ב' וחומה עד 31/3/2026 | P7: קבלן יצא מהשטח, בוצעה ישיבת התנעה עבור השלמות שלב א', שלב ב' (מבנה) והוספת שנאי WBE200 נדרש RFT עבור תכולה מאוחדת WBE-125 שלב א', שלב ב' וחומה עד 31/3/2026 | Q7: קבלן יצא מהשטח, בוצעה ישיבת התנעה עבור השלמות שלב א', שלב ב' (מבנה) והוספת שנאי WBE200 נדרש RFT עבור תכולה מאוחדת WBE-125 שלב א', שלב ב' וחומה עד 31/3/2026 | R7: קבלן יצא מהשטח, בוצעה ישיבת התנעה עבור השלמות שלב א', שלב ב' (מבנה) והוספת שנאי WBE200 נדרש RFT עבור תכולה מאוחדת WBE-125 שלב א', שלב ב' וחומה עד 31/3/2026 | S7: בתכנון לצורך עדכון תכניות וכ"כ עבור איחוד שלבים נדרש RFT עבור תכולה מאוחדת WBE-125 שלב א', שלב ב' וחומה עד 31/3/2026 | T7: בתכנון לצורך עדכון תכניות וכ"כ עבור איחוד שלבים נדרש RFT עבור תכולה מאוחדת WBE-125 שלב א', שלב ב' וחומה עד 31/3/2026 נדרש לבנות את כ"כ לפי חוזה הקמות ישן מאחר והמבנה כבר בנוי כך | U7: בתכנון לצורך עדכון תכניות וכ"כ עבור איחוד שלבים נדרש RFT עבור תכולה מאוחדת WBE-125 שלב א', שלב ב' וחומה עד 31/3/2026 נדרש לבנות את כ"כ לפי חוזה הקמות ישן מאחר והמבנה כבר בנוי כך | V7: בתכנון לצורך עדכון תכניות וכ"כ עבור איחוד שלבים נדרש RFT עבור תכולה מאוחדת WBE-125 שלב א', שלב ב' וחומה עד 31/3/2026 נדרש לבנות את כ"כ לפי חוזה הקמות ישן מאחר והמבנה כבר בנוי כך | W7: בתכנון לצורך עדכון תכניות וכ"כ עבור איחוד שלבים נדרש RFT עבור תכולה מאוחדת WBE-125 שלב א', שלב ב' וחומה עד 31/3/2026 נדרש לבנות את כ"כ לפי חוזה הקמות ישן מאחר והמבנה כבר בנוי כך | X7: נדרש הירתמות התכנון לאיחוד התכולות ליציאה ל RFT חדש תוך זמן קצר | Y7: חסם לטיפול מנהל מגזר תכנון
B8: WBE-200 | C8: תמנע-הוספת שנאי שני 50 מגוו"א | D8: הרחבה | E8: אוחייון, איתן | F8: בסיל כהן יפעת | G8: 46691 | H8: 46721 | J8: הקפאת תכולה | K8: ="WBS: " & B8 & CHAR(10) & "שם פרויקט: " & C8 & CHAR(10) & "מנה״פ: " & E8 & CHAR(10) & "יעד תכנית פיתוח: " & TEXT(G8,"dd/mm/yyyy") & CHAR(10) & "יעד מסתמן: " & TEXT(H8,"dd/mm/yyyy") -> WBS: WBE-200 שם פרויקט: תמנע-הוספת שנאי שני 50 מגוו"א מנה״פ: אוחייון, איתן יעד תכנית פיתוח: 31/10/2027 יעד מסתמן: 30/11/2027 | M8: הוגשה בקשה לקדם בתכנון להוסיף כתכולה לקבלן שיבחר ל WBE125 | N8: הוגשה בקשה לקדם בתכנון להוסיף כתכולה לקבלן שיבחר ל WBE125 נדרש תכנון אזרחי לביצוע WBE-200 עד 31/12/2026 | O8: הוגשה בקשה לקדם בתכנון להוסיף כתכולה לקבלן שיבחר ל WBE125 נדרש תכנון אזרחי לביצוע WBE-200 עד 31/12/2026 | P8: הוגשה בקשה לקדם בתכנון להוסיף כתכולה לקבלן שיבחר ל WBE125 נדרש תכנון אזרחי לביצוע WBE-200 עד 31/12/2026 | Q8: הוגשה בקשה לקדם בתכנון להוסיף כתכולה לקבלן שיבחר ל WBE125 נדרש תכנון אזרחי לביצוע WBE-200 עד 31/12/2026 | R8: הוגשה בקשה לקדם בתכנון להוסיף כתכולה לקבלן שיבחר ל WBE125 נדרש תכנון אזרחי לביצוע WBE-200 עד 31/12/2026 | S8: הוגשה בקשה לקדם בתכנון להוסיף כתכולה לקבלן שיבחר ל WBE125 נדרש תכנון אזרחי לביצוע WBE-200 עד 31/12/2026 | T8: הוגשה בקשה לקדם בתכנון להוסיף כתכולה לקבלן שיבחר ל WBE125 נדרש תכנון אזרחי לביצוע WBE-200 עד 31/12/2026 | U8: הוגשה בקשה לקדם בתכנון להוסיף כתכולה לקבלן שיבחר ל WBE125 נדרש תכנון אזרחי לביצוע WBE-200 עד 31/12/2026 | V8: הוגשה בקשה לקדם בתכנון להוסיף כתכולה לקבלן שיבחר ל WBE125 נדרש תכנון אזרחי לביצוע WBE-200 עד 31/12/2026 | W8: הוגשה בקשה לקדם בתכנון להוסיף כתכולה לקבלן שיבחר ל WBE125 נדרש תכנון אזרחי לביצוע WBE-200 עד 31/12/2026 | AD8: ="WBS: " & B8 & CHAR(10) & "שם פרויקט: " & D8 & CHAR(10) & "מנה״פ: " & E8 & CHAR(10) & "יעד תכנית פיתוח: " & TEXT(G8,"dd/mm/yyyy") & CHAR(10) & "יעד מסתמן: " & TEXT(H8,"dd/mm/yyyy") -> WBS: WBE-200 שם פרויקט: הרחבה מנה״פ: אוחייון, איתן יעד תכנית פיתוח: 31/10/2027 יעד מסתמן: 30/11/2027
B9: WBE-235 | C9: צומת כרמיה – הקמת 2 שדות מ"ע חדשים והתאמת שדה 1 לזרם 2000 א'. משיק ל-WBO-824, WBO-823 . | D9: הרחבה | E9: אוחייון, איתן | F9: בסיל כהן יפעת | G9: 46568 | H9: 46751 | J9: בחירת קבלן | K9: ="WBS: " & B9 & CHAR(10) & "שם פרויקט: " & C9 & CHAR(10) & "מנה״פ: " & E9 & CHAR(10) & "יעד תכנית פיתוח: " & TEXT(G9,"dd/mm/yyyy") & CHAR(10) & "יעד מסתמן: " & TEXT(H9,"dd/mm/yyyy") -> WBS: WBE-235 שם פרויקט: צומת כרמיה – הקמת 2 שדות מ"ע חדשים והתאמת שדה 1 לזרם 2000 א'. משיק ל-WBO-824, WBO-823 . מנה״פ: אוחייון, איתן יעד תכנית פיתוח: 30/06/2027 יעד מסתמן: 30/12/2027 | M9: בשבוע שעבר עבר RFT, ממתין לאישור נספח 5 ואומדנים עבור השו"שיים. יש לקבל הזמנה מתכנון א"מ עבור חפירות גישוש | N9: ממתין לאישור נספח 5 ואומדנים עבור השו"שיים. יש לקבל הזמנה מתכנון א"מ עבור חפירות גישוש תכולת שדרוג שדה 1 נכנסת תלתכולת שלב א' - נדרש אישור כוחות לפורטל לקידום תכנון של הולכה | O9: ממתין לאישור נספח 5 יש לקבל הזמנה מתכנון א"מ עבור חפירות גישוש תכולת שדרוג שדה 1 נכנסת תלתכולת שלב א' - נדרש אישור כוחות לפורטל לקידום תכנון של הולכה | P9: יש לקבל הזמנה מתכנון א"מ עבור חפירות גישוש תכולת שדרוג שדה 1 נכנסת תלתכולת שלב א' - נדרש אישור כוחות לפורטל לקידום תכנון של הולכה | Q9: יש לקבל הזמנה מתכנון א"מ עבור חפירות גישוש נגה לא מאשרים הפסקת שדה 1 בסתיו 2026 | R9: הועברה הזמנה לחפירות גישוש מכרז להקמת שדות תקוע ברכש | S9: הועברה הזמנה לחפירות גישוש מכרז להקמת שדות תקוע ברכש - יעד לקבלן 5/2026 | T9: הועברה הזמנה לחפירות גישוש מכרז להקמת שדות הוכנס לרשימת תיעדוף ברכש - יעד לקבלן 5/2026 | U9: הועברה הזמנה לחפירות גישוש מכרז להקמת שדות הוכנס לרשימת תיעדוף ברכש - יעד לקבלן 5/2026 | V9: יצאה הזמנה לחפירות גישוש סיור קבלנים מתוכנן ב 19/3/2026 צפי קבלן זוכה 30/5/2026 | W9: יצאה הזמנה לחפירות גישוש - יתכן ולא תמומש בשל הסמיכות לעלית קבלן לקרקע התקיים סיור קבלנים מתוכנן ב 19/3/2026 צפי קבלן זוכה 15/4/2026
A10: כן | B10: WBE-260 | C10: מצפה רמון - התקנת שנאי מס' 531- מערכתי | D10: הרחבה | E10: אוחייון, איתן | F10: בסיל כהן יפעת | G10: 46265 | H10: 46446 | J10: בחירת קבלן | K10: ="WBS: " & B10 & CHAR(10) & "שם פרויקט: " & C10 & CHAR(10) & "מנה״פ: " & E10 & CHAR(10) & "יעד תכנית פיתוח: " & TEXT(G10,"dd/mm/yyyy") & CHAR(10) & "יעד מסתמן: " & TEXT(H10,"dd/mm/yyyy") -> WBS: WBE-260 שם פרויקט: מצפה רמון - התקנת שנאי מס' 531- מערכתי מנה״פ: אוחייון, איתן יעד תכנית פיתוח: 31/08/2026 יעד מסתמן: 28/02/2027 | M10: נמצא במחלקת מכרזים, עדיין לא פורסם המכרז. התקבל מבנה ברזל, מכולת מ"ג ראשונה צפויה להתקבל השבוע | N10: נקבע סיור קבלנים מכולת מ"ג ראשונה התקבלה | O10: נקבע סיור קבלנים מכולת מ"ג ראשונה התקבלה | P10: נקבע סיור קבלנים 5/2 מכולת מ"ג ראשונה התקבלה שניה צפויה השבוע | Q10: התקיים סיור קבלנים, צפי לקבלן במחצית מרץ 2026 התקבלו מכולות מ"ג | R10: התקיים סיור קבלנים, צפי לקבלן במחצית מרץ 2026 התקבלו מכולות מ"ג | S10: הגשת הצעות קבלנים 26/2/2026 | T10: צפי לקבלן זוכה 15/3/2026 | U10: צפי לקבלן זוכה 15/3/2026 | V10: צפי לקבלן זוכה בשבוע הקרוב תחילת עבודות 30/4/2026 | W10: צפי לקבלן זוכה בשבוע הקרוב תחילת עבודות 30/4/2026 | X10: אי עמידה בתכנית פיתוח לאחר שקבלן יתחיל בעבודות נדרש לבצע עדכון מול נוגה | Y10: חסם לטיפול רב פרויקטלי
A11: כן | B11: WBE-259 | C11: מצפה רמון - החלפת שנאי מס' 532- מערכתי | D11: הרחבה | E11: אוחייון, איתן | F11: בסיל כהן יפעת | G11: 46507 | H11: 46690 | J11: הקפאת תצורה | K11: ="WBS: " & B11 & CHAR(10) & "שם פרויקט: " & C11 & CHAR(10) & "מנה״פ: " & E11 & CHAR(10) & "יעד תכנית פיתוח: " & TEXT(G11,"dd/mm/yyyy") & CHAR(10) & "יעד מסתמן: " & TEXT(H11,"dd/mm/yyyy") -> WBS: WBE-259 שם פרויקט: מצפה רמון - החלפת שנאי מס' 532- מערכתי מנה״פ: אוחייון, איתן יעד תכנית פיתוח: 30/04/2027 יעד מסתמן: 30/10/2027 | M11: תכולה אזרחית נכללה כאופציה במכרז של WBE260. לאחר שיבחר קבלן ובהתאם לביצועים שלו יוחלט אם נדרש תכנון למכרז או לביצוע | N11: תכולה אזרחית נכללה כאופציה במכרז של WBE260. לאחר שיבחר קבלן ובהתאם לביצועים שלו יוחלט אם נדרש תכנון למכרז או לביצוע | O11: תכולה אזרחית נכללה כאופציה במכרז של WBE260. לאחר שיבחר קבלן ובהתאם לביצועים שלו יוחלט אם נדרש תכנון למכרז או לביצוע | P11: תכולה אזרחית נכללה כאופציה במכרז של WBE260. לאחר שיבחר קבלן ובהתאם לביצועים שלו יוחלט אם נדרש תכנון למכרז או לביצוע | Q11: תכולה אזרחית נכללה כאופציה במכרז של WBE260. לאחר שיבחר קבלן ובהתאם לביצועים שלו יוחלט אם נדרש תכנון למכרז או לביצוע | R11: תכולה אזרחית נכללה כאופציה במכרז של WBE260. לאחר שיבחר קבלן ובהתאם לביצועים שלו יוחלט אם נדרש תכנון למכרז או לביצוע | S11: תכולה אזרחית נכללה כאופציה במכרז של WBE260. לאחר שיבחר קבלן ובהתאם לביצועים שלו יוחלט אם נדרש תכנון למכרז או לביצוע | T11: תכולה אזרחית נכללה כאופציה במכרז של WBE260. לאחר שיבחר קבלן ובהתאם לביצועים שלו יוחלט אם נדרש תכנון למכרז או לביצוע אושרה דחיה של ת.פ. ל 30/4/2027 בהתאם למצב, תידרש דחיה נוספת | U11: תכולה אזרחית נכללה כאופציה במכרז של WBE260. לאחר שיבחר קבלן ובהתאם לביצועים שלו יוחלט אם נדרש תכנון למכרז או לביצוע אושרה דחיה של ת.פ. ל 30/4/2027 בהתאם למצב, תידרש דחיה נוספת | V11: תכולה אזרחית נכללה כאופציה במכרז של WBE260. לאחר שיבחר קבלן ובהתאם לביצועים שלו יוחלט אם נדרש תכנון למכרז או לביצוע | W11: תכולה אזרחית נכללה כאופציה במכרז של WBE260. לאחר שיבחר קבלן ובהתאם לביצועים שלו יוחלט אם נדרש תכנון למכרז או לביצוע | X11: אי עמידה בתכנית פיתוח לאחר שקבלן יתחיל בעבודות נדרש לבצע עדכון מול נוגה | Y11: חסם לטיפול רב פרויקטלי
B12: WBE-118 | C12: יוטבתה - החלפת שנאי 531 ועיגון השנאי | D12: הרחבה | E12: אוחייון, איתן | F12: בסיל כהן יפעת | G12: 46752 | H12: 46568 | J12: הקפאת תצורה | K12: ="WBS: " & B12 & CHAR(10) & "שם פרויקט: " & C12 & CHAR(10) & "מנה״פ: " & E12 & CHAR(10) & "יעד תכנית פיתוח: " & TEXT(G12,"dd/mm/yyyy") & CHAR(10) & "יעד מסתמן: " & TEXT(H12,"dd/mm/yyyy") -> WBS: WBE-118 שם פרויקט: יוטבתה - החלפת שנאי 531 ועיגון השנאי מנה״פ: אוחייון, איתן יעד תכנית פיתוח: 31/12/2027 יעד מסתמן: 30/06/2027 | M12: השנאי הוחלף, לא בוצעו תכולות אזרחיות. יבוצעו בסיום WBE202 הוספת שנאי 533 | N12: השנאי הוחלף, לא בוצעו תכולות אזרחיות. יבוצעו בסיום WBE202 הוספת שנאי 533 | O12: השנאי הוחלף, לא בוצעו תכולות אזרחיות. יבוצעו בסיום WBE202 הוספת שנאי 533 הוגשה בקשה להכללת התכולות הנותרות בפרויקט ההרחבה WBE-120 | P12: השנאי הוחלף, לא בוצעו תכולות אזרחיות. יבוצעו בסיום WBE202 הוספת שנאי 533 הוגשה בקשה להכללת התכולות הנותרות בפרויקט ההרחבה WBE-120 | Q12: השנאי הוחלף, לא בוצעו תכולות אזרחיות. יבוצעו בסיום WBE202 הוספת שנאי 533 הוגשה בקשה להכללת התכולות הנותרות בפרויקט ההרחבה WBE-120 | R12: השנאי הוחלף, לא בוצעו תכולות אזרחיות. יבוצעו בסיום WBE202 הוספת שנאי 533 הוגשה בקשה להכללת התכולות הנותרות בפרויקט ההרחבה WBE-120 | S12: השנאי הוחלף, לא בוצעו תכולות אזרחיות. יבוצעו בסיום WBE202 הוספת שנאי 533 הוגשה בקשה להכללת התכולות הנותרות בפרויקט ההרחבה WBE-120 | T12: השנאי הוחלף, לא בוצעו תכולות אזרחיות. יבוצעו בסיום WBE202 הוספת שנאי 533 הוגשה בקשה להכללת התכולות הנותרות בפרויקט ההרחבה WBE-120 | U12: השנאי הוחלף, לא בוצעו תכולות אזרחיות. יבוצעו בסיום WBE202 הוספת שנאי 533 הוגשה בקשה להכללת התכולות הנותרות בפרויקט ההרחבה WBE-120 | V12: השנאי הוחלף, לא בוצעו תכולות אזרחיות. יבוצעו בסיום WBE202 הוספת שנאי 533 הוגשה בקשה להכללת התכולות הנותרות בפרויקט ההרחבה WBE-120 | W12: השנאי הוחלף, לא בוצעו תכולות אזרחיות. יבוצעו בסיום WBE202 הוספת שנאי 533 הוגשה בקשה להכללת התכולות הנותרות בפרויקט ההרחבה WBE-120
B13: WBE-120 | C13: יוטבתה-שדרוג התחמ"ש-רב שלבי | D13: הרחבה | E13: אוחייון, איתן | F13: בסיל כהן יפעת | G13: 46325 | H13: 46446 | J13: הרכבה חשמלית | K13: ="WBS: " & B13 & CHAR(10) & "שם פרויקט: " & C13 & CHAR(10) & "מנה״פ: " & E13 & CHAR(10) & "יעד תכנית פיתוח: " & TEXT(G13,"dd/mm/yyyy") & CHAR(10) & "יעד מסתמן: " & TEXT(H13,"dd/mm/yyyy") -> WBS: WBE-120 שם פרויקט: יוטבתה-שדרוג התחמ"ש-רב שלבי מנה״פ: אוחייון, איתן יעד תכנית פיתוח: 30/10/2026 יעד מסתמן: 28/02/2027 | M13: חדר פיקוד הסתיים אזרחי, שדות 3,9 בשלבי סיום. מתוכננת מסירה ב 19/1/2026 | N13: חדר פיקוד הסתיים אזרחי, שדות 3,9 בשלבי סיום. מתוכננת מסירה ב 19/1/2026 | O13: חדר פיקוד הסתיים אזרחי, שדות 3,9 בשלבי סיום. מתוכננת מסירה לאחר תיקון רג'קטים ב 28/1/2026 | P13: נמסר להרכבה חשמלית | Q13: נמסר להרכבה חשמלית | R13: נמסר להרכבה חשמלית | S13: נמסר להרכבה חשמלית | T13: נמסר להרכבה חשמלית שלא מבצעים עבודה באתר בגלל תיעדוף ומהיום גם המלחמה קוי פיקוד שתוכננו לא מתאימים לשטח וכעת מנסים למצוא פתרון להעברת קוי הפיקוד לשדות החדשים | U13: הרכבה חשמלית הודיעו שנכנסים היום לעבודה 8/3/2026 קוי פיקוד שתוכננו לא מתאימים לשטח וכעת מנסים למצוא פתרון להעברת קוי הפיקוד לשדות החדשים | V13: בשלב ברכבת ציות מ"ע בשדות נדרש ליישם פתרון להעברת קווי פיקוד לשדות החדשים לפני סיום עבודות הקבלן לשלב א' | W13: בשלב הרכבת ציוד מ"ע בשדות השבוע מתוכנן חיבור צנרת פיקוד מהשדות למבנה הפיקוד והעברת כבל מ"ג המתוכנן לשנאים 531 ו 533
B14: WBE-202 | C14: יוטבתה-הוספת שנאי 532 161/36 ק"ו 50 מגוו"א | D14: הרחבה | E14: אוחייון, איתן | F14: בסיל כהן יפעת | G14: 46325 | H14: 46446 | J14: עבודה אזרחית | K14: ="WBS: " & B14 & CHAR(10) & "שם פרויקט: " & C14 & CHAR(10) & "מנה״פ: " & E14 & CHAR(10) & "יעד תכנית פיתוח: " & TEXT(G14,"dd/mm/yyyy") & CHAR(10) & "יעד מסתמן: " & TEXT(H14,"dd/mm/yyyy") -> WBS: WBE-202 שם פרויקט: יוטבתה-הוספת שנאי 532 161/36 ק"ו 50 מגוו"א מנה״פ: אוחייון, איתן יעד תכנית פיתוח: 30/10/2026 יעד מסתמן: 28/02/2027 | M14: יבוצע בסיום WBE120 | N14: יבוצע בסיום WBE120 | O14: יבוצע בסיום WBE120 | P14: יבוצע בסיום WBE120 | Q14: יבוצע בסיום WBE120 | R14: יבוצע בסיום WBE120 | S14: יבוצע בסיום WBE120 | T14: יבוצע בסיום WBE120 | U14: יבוצע בסיום WBE120 | V14: יבוצע בסיום WBE120 | W14: יבוצע בסיום WBE120
B15: WBC-099 | C15: אשקלון צפון-הקמת תחמ"ש חיצונית 161/24 ק" | D15: הקמה | E15: אוחייון, איתן | F15: בסיל כהן יפעת | G15: 46476 | H15: 46660 | J15: קבלת היתר | K15: ="WBS: " & B15 & CHAR(10) & "שם פרויקט: " & C15 & CHAR(10) & "מנה״פ: " & E15 & CHAR(10) & "יעד תכנית פיתוח: " & TEXT(G15,"dd/mm/yyyy") & CHAR(10) & "יעד מסתמן: " & TEXT(H15,"dd/mm/yyyy") -> WBS: WBC-099 שם פרויקט: אשקלון צפון-הקמת תחמ"ש חיצונית 161/24 ק" מנה״פ: אוחייון, איתן יעד תכנית פיתוח: 30/03/2027 יעד מסתמן: 30/09/2027 | M15: ממתין לתשובת תכנון לגבי שוחות מ"ג וכן ל ASMADE מביצוע מ"ג להשלמת DR, צפי לניתר 3-4/2026 | N15: ממתין לתשובת תכנון לגבי שוחות מ"ג וכן ל ASMADE מביצוע מ"ג להשלמת DR, צפי להיתר 3-4/2026 | O15: ממתין לתשובת תכנון לגבי שוחות מ"ג וכן ל ASMADE מביצוע מ"ג. הופץ RFT, צפי להיתר 3-4/2026 | P15: ממתין לתשובת תכנון לגבי שוחות מ"ג וכן ל ASMADE מביצוע מ"ג. הופץ RFT, צפי להיתר 5/2026 | Q15: ממתין לתשובת תכנון לגבי שוחות מ"ג וכן ל ASMADE מביצוע מ"ג. הופץ RFT, צפי להיתר 5/2026 | R15: ממתין לתשובת תכנון לגבי שוחות מ"ג וכן ל ASMADE מביצוע מ"ג. הופץ RFT, צפי להיתר 5/2026 | S15: ממתין לתשובת תכנון לגבי שוחות מ"ג וכן ל ASMADE מביצוע מ"ג. ממתין ברכש ליציאה למכרז ,צפי להיתר נדחה ל 7/2026 | T15: ממתין לתשובת תכנון לגבי שוחות מ"ג וכן ל ASMADE מביצוע מ"ג. ממתין ברכש ליציאה למכרז ,צפי להיתר נדחה ל 7/2026 | U15: ממתין לתשובת תכנון לגבי שוחות מ"ג וכן ל ASMADE מביצוע מ"ג. ממתין ברכש ליציאה למכרז ,צפי להיתר נדחה ל 7/2026 | V15: ממתין לתשובת תכנון לגבי שוחות מ"ג וכן ל ASMADE מביצוע מ"ג. ברכש ליציאה למכרז, צפי קבלן זוכה 30/5/2026 ,צפי להיתר 6/2026 | W15: ממתין לתשובת תכנון לגבי שוחות מ"ג וכן ל ASMADE מביצוע מ"ג. ברכש ליציאה למכרז, צפי קבלן זוכה 30/5/2026 ,צפי להיתר 6/2026
B16: WBD-001 | C16: שפרעם ניידת-פירוק התחמ"ש הניידת | D16: ניידת | E16: אוחנה, אלי | F16: הלוי בת אל | G16: 46506 | H16: 46476 | K16: ="WBS: " & B16 & CHAR(10) & "שם פרויקט: " & C16 & CHAR(10) & "מנה״פ: " & E16 & CHAR(10) & "יעד תכנית פיתוח: " & TEXT(G16,"dd/mm/yyyy") & CHAR(10) & "יעד מסתמן: " & TEXT(H16,"dd/mm/yyyy") -> WBS: WBD-001 שם פרויקט: שפרעם ניידת-פירוק התחמ"ש הניידת מנה״פ: אוחנה, אלי יעד תכנית פיתוח: 29/04/2027 יעד מסתמן: 30/03/2027 | M16: בטיפול המחוז להסטת תשתיות | N16: בטיפול המחוז להסטת תשתיות | O16: בטיפול המחוז להסטת תשתיות | P16: בטיפול המחוז להסטת תשתיות | Q16: בטיפול המחוז להסטת תשתיות | R16: בטיפול המחוז להסטת תשתיות | S16: בטיפול המחוז להסטת תשתיות | T16: בטיפול המחוז להסטת תשתיות | U16: בטיפול המחוז להסטת תשתיות | V16: בטיפול המחוז להסטת תשתיות | W16: בטיפול המחוז להסטת תשתיות
A17: כן | B17: WBC-121 | C17: רוקח(רמת אביב חדשה)-הקמת תחמ"ש פנימית | D17: הקמה | E17: אוחנה, אלי | F17: הלוי בת אל | G17: 46721 | H17: 47117 | J17: קבלת היתר | K17: ="WBS: " & B17 & CHAR(10) & "שם פרויקט: " & C17 & CHAR(10) & "מנה״פ: " & E17 & CHAR(10) & "יעד תכנית פיתוח: " & TEXT(G17,"dd/mm/yyyy") & CHAR(10) & "יעד מסתמן: " & TEXT(H17,"dd/mm/yyyy") -> WBS: WBC-121 שם פרויקט: רוקח(רמת אביב חדשה)-הקמת תחמ"ש פנימית מנה״פ: אוחנה, אלי יעד תכנית פיתוח: 30/11/2027 יעד מסתמן: 30/12/2028 | M17: החלטות הוועדה אמורות להתקבל עד 14/01/2026 לצורך המשך התהליך לשלב התכן טרם הוסדר נושא רכישת הקרקע המהווה חסם להיתר. | N17: התקבלה החלטת הוועדה לעבור לשלב התכן, מבוצע השלמת הדרישות והאישורים הנדרשים. טרם הוסדר נושא רכישת הקרקע המהווה חסם להיתר. החל תהליך הכנת החומר למכרז הקבלנים. | O17: התקבלה החלטת הוועדה לעבור לשלב התכן, מבוצע השלמת הדרישות והאישורים הנדרשים. טרם הוסדר נושא רכישת הקרקע המהווה חסם להיתר. החל תהליך הכנת החומר למכרז הקבלנים. | P17: התקבלה החלטת הוועדה לעבור לשלב התכן, מבוצע השלמת הדרישות והאישורים הנדרשים. טרם הוסדר נושא רכישת הקרקע המהווה חסם להיתר. החל תהליך הכנת החומר למכרז הקבלנים. | Q17: התקבלה החלטת הוועדה לעבור לשלב התכן, מבוצע השלמת הדרישות והאישורים הנדרשים. טרם הוסדר נושא רכישת הקרקע המהווה חסם להיתר. החל תהליך הכנת החומר למכרז הקבלנים. 22.02.2026- צפי לסיור קבלנים טרם הוסרה תשתית קו הביוב משטח התחנה- באחריות עיריית תל אביב | R17: התקבלה החלטת הוועדה לעבור לשלב התכן, מבוצע השלמת הדרישות והאישורים הנדרשים. טרם הוסדר נושא רכישת הקרקע המהווה חסם להיתר. החל תהליך הכנת החומר למכרז הקבלנים. 17.02.2026- צפי לסיור קבלנים טרם הוסרה תשתית קו הביוב משטח התחנה- באחריות עיריית תל אביב | S17: התקבלה החלטת הוועדה לעבור לשלב התכן, מבוצע השלמת הדרישות והאישורים הנדרשים. טרם הוסדר נושא רכישת הקרקע המהווה חסם להיתר. החל תהליך הכנת החומר למכרז הקבלנים. 17.02.2026- בוצע סיור קבלנים טרם הוסרה תשתית קו הביוב משטח התחנה- באחריות עיריית תל אביב 22/02/2026- סיור לכריתת העתקת עצים, עפ"י דרישת האגרונום העירוני, ביצוע העתקת עצים עד 04/2026 (אחרת נידרש להעתיק רק בעוד כחצי שנה) לכן נדרש פינוי התשתיות ברכישת השטח במיידי | T17: התקבלה החלטת הוועדה לעבור לשלב התכן, מבוצע השלמת הדרישות והאישורים הנדרשים. טרם הוסדר נושא רכישת הקרקע המהווה חסם להיתר. החל תהליך הכנת החומר למכרז הקבלנים. 17.02.2026- בוצע סיור קבלנים טרם הוסרה תשתית קו הביוב משטח התחנה- באחריות עיריית תל אביב ביצוע העתקת עצים עד 04/2026 (אחרת נידרש להעתיק רק בעוד כחצי שנה) לכן נדרש פינוי התשתיות ברכישת השטח במיידי החל תהליך של מכרז ספק יחיד לצורך כריתת העצים | U17: התקבלה החלטת הוועדה לעבור לשלב התכן, מבוצע השלמת הדרישות והאישורים הנדרשים. טרם הוסדר נושא רכישת הקרקע המהווה חסם להיתר. ממתינים להצעות מחיר הקבלנים. טרם הוסרה תשתית קו הביוב משטח התחנה- באחריות עיריית תל אביב. החל תהליך של מכרז ספק יחיד לצורך כריתת העצים. | V17: ממתינים לאישור כיבוי אש ובקשה להיתר טרם הוסדר נושא רכישת הקרקע המהווה חסם להיתר. ממתינים להצעות מחיר הקבלנים. טרם הוסרה תשתית קו הביוב משטח התחנה- באחריות עיריית תל אביב. (הנושא הוסדר עם גורמי העירייה בסיום כריתת העצים, ההעתקה תבוצע) החל תהליך של מכרז ספק יחיד לצורך כריתת העצים. | W17: ממתינים לאישור כיבוי אש ובקשה להיתר טרם הוסדר נושא רכישת הקרקע המהווה חסם להיתר. ממתינים להצעות מחיר הקבלנים. טרם הוסרה תשתית קו הביוב משטח התחנה- באחריות עיריית תל אביב. (הנושא הוסדר עם גורמי העירייה בסיום כריתת העצים, ההעתקה תבוצע) נבחר ספק יחיד לצורך כריתת העצים, צפי תחילת עבודות 25.03.2026 | X17: העתקת עצים השלמת תהליך רכישת הקרקע ע"י מנר"א עמידת ההולכה בלו"ז לביצוע תשתית מ"ע. | Y17: חסם לטיפול מנהל אגף
A18: כן | B18: WBD-124 | C18: חפר ארעית- הקמת תחמ"ש ארעית | D18: ניידת | E18: אוחנה, אלי | F18: הלוי בת אל | G18: 46203 | H18: 46203 | J18: עבודה אזרחית | K18: ="WBS: " & B18 & CHAR(10) & "שם פרויקט: " & C18 & CHAR(10) & "מנה״פ: " & E18 & CHAR(10) & "יעד תכנית פיתוח: " & TEXT(G18,"dd/mm/yyyy") & CHAR(10) & "יעד מסתמן: " & TEXT(H18,"dd/mm/yyyy") -> WBS: WBD-124 שם פרויקט: חפר ארעית- הקמת תחמ"ש ארעית מנה״פ: אוחנה, אלי יעד תכנית פיתוח: 30/06/2026 יעד מסתמן: 30/06/2026 | M18: המשך עבודות הקמה של הארעית, מבוצעות בשטח עבודות לשיפור מעברים וגידור לצורך הרכבת הציודים החשמליים. בעקבות פגעי מזג האויר נדרשים עבודות שיקום של גדרות היקפיים בתחנה. | N18: עיכוב בעבודות אזרחיות להקמת הארעית בשל מחסור בכ"א בפועלים. הרכבות, תמיכות וציוד חשמלי כולל חיווט במסדרי 161 ק"ו ו- 24 ק"ו. עיכוב בבדיקות מכולות פיקוד ומסדרי 24 ק"ו (קיים מחסור בבודקים) | O18: עיכוב בעבודות אזרחיות להקמת הארעית בשל מחסור בכ"א בפועלים. הרכבות, תמיכות וציוד חשמלי כולל חיווט במסדרי 161 ק"ו ו- 24 ק"ו. עיכוב בבדיקות מכולות פיקוד ומסדרי 24 ק"ו (קיים מחסור בבודקים) עצירה ניכרת בעבודות הביצוע עקב מחסור בכ"א מתמשך | P18: עיכוב בעבודות אזרחיות להקמת הארעית בשל מחסור בכ"א בפועלים. הרכבות, תמיכות וציוד חשמלי כולל חיווט במסדרי 161 ק"ו ו- 24 ק"ו. עיכוב בבדיקות מכולות פיקוד ומסדרי 24 ק"ו (קיים מחסור בבודקים) עצירה ניכרת בעבודות הביצוע עקב מחסור בכ"א מתמשך | Q18: המשך עבודות התקנת ציוד ועבודות פיתוח שטח | R18: המשך עבודות התקנת ציוד ועבודות פיתוח שטח | S18: המשך עבודות התקנת ציוד ועבודות פיתוח שטח ישנן תקלות בשנאים כולל השנאי החדש- בטיפול הביצוע | T18: המשך עבודות התקנת ציוד ועבודות פיתוח שטח (כרגע עצירת עבודות בשל המצב הביטחוני) ישנן תקלות בשנאים כולל השנאי החדש- בטיפול הביצוע | U18: המשך עבודות התקנת ציוד ועבודות פיתוח שטח לאחר עיכוב של שבוע בשל המצב הבטחוני. ישנן תקלות בשנאים כולל השנאי החדש- בטיפול הביצוע | V18: בוצע סיור למסירת עבודה אזרחית, ישנם מספר רג'קטים קטנים לתיקון טיפול שמן לשנאי 522 יבוצע ב 17.03.2026 קיים מחסור בבודקים מזה כשלושה שבועות | W18: בוצע סיור למסירת עבודה אזרחית, ישנם מספר רג'קטים קטנים לתיקון לאור המצב הבטחוני/מזג האויר וחופשת הפסח המתקרבת מסתמן עיכוב בהכנסה לניצול של התחנה של כחודש | X18: נדרש תגבור של כ"א כללי לתחנה- קבלנים, ביצוע ובודקים | Y18: חסם לטיפול מנהל אגף | Z18: חסם לטיפול מנהלת מחלקה | AE18: חסם לטיפול מנהל אגף תפעול השנאה
B19: WBJ-004 | C19: חפר-הקמת תחמ"ג 400/161 ק"ו,650*3 מגוו"א- שנאי קישור שלישי 454 יותקן ולא יחושמל-רב שלבי | D19: ניידת | E19: אוחנה, אלי | F19: הלוי בת אל | G19: 46873 | H19: 46964 | J19: עבודה אזרחית | K19: ="WBS: " & B19 & CHAR(10) & "שם פרויקט: " & C19 & CHAR(10) & "מנה״פ: " & E19 & CHAR(10) & "יעד תכנית פיתוח: " & TEXT(G19,"dd/mm/yyyy") & CHAR(10) & "יעד מסתמן: " & TEXT(H19,"dd/mm/yyyy") -> WBS: WBJ-004 שם פרויקט: חפר-הקמת תחמ"ג 400/161 ק"ו,650*3 מגוו"א- שנאי קישור שלישי 454 יותקן ולא יחושמל-רב שלבי מנה״פ: אוחנה, אלי יעד תכנית פיתוח: 30/04/2028 יעד מסתמן: 30/07/2028 | M19: נבחר קבלן ואושר ע"י הדריקטריון, צפי לישיבת תיאום עם הפיקוח האזרחי בשבוע הבא. בעקבות פגעי מזג האויר נדרשים עבודות שיקום של גדרות היקפיים בתחנה. | N19: נקבעה ישיבת התנעה עם קבלן זוכה לשלב ב' | O19: בוצעה ישיבת התנעה עם קבלן זוכה לשלב ב' | P19: ממתינים לסיום חתימת החוזה ותחילת העבודה של הקבלן האזרחי | Q19: ממתינים לסיום חתימת החוזה ותחילת העבודה של הקבלן האזרחי | R19: הסתיים חתימת החוזה ממתינים לתחילת העבודה של הקבלן האזרחי | S19: הסתיים חתימת החוזה ממתינים לתחילת העבודה של הקבלן האזרחי עיכוב בתחילת עבודות מסדר 400 ק"ו מאחר ונתוני הציוד טרם התקבלו וכמו כן טרם נבחר ספק זוכה ולכן ביצוע תכנון אלק"מ ואזרחי לא החל. (צפי תחילת עבודות 07-08/2026 ייעכב את תחילת העבודות של הקבלן שנבחר. | T19: הסתיים חתימת החוזה ממתינים לתחילת העבודה של הקבלן האזרחי בוצעה ישיבה עם יוסי כהן ונווה כהן לצורך תיאום שלבי קבלת נתוני הציוד וביצוע תוכניות בשלבים על מנת להימנע מעצירת עבודות הקבלן האזרחי | U19: ממתינים לתחילת העבודה של הקבלן האזרחי. בוצעה ישיבה עם יוסי כהן ונווה כהן לצורך תיאום שלבי קבלת נתוני הציוד וביצוע תוכניות בשלבים על מנת להימנע מעצירת עבודות הקבלן האזרחי | V19: ממתינים לתחילת העבודה של הקבלן האזרחי. בוצעה ישיבה עם יוסי כהן ונווה כהן לצורך תיאום שלבי קבלת נתוני הציוד וביצוע תוכניות בשלבים על מנת להימנע מעצירת עבודות הקבלן האזרחי | W19: ממתינים לתחילת העבודה של הקבלן האזרחי. בוצעה ישיבה עם יוסי כהן ונווה כהן לצורך תיאום שלבי קבלת נתוני הציוד וביצוע תוכניות בשלבים על מנת להימנע מעצירת עבודות הקבלן האזרחי | X19: השלמת תכנון של מסדרי 400 ק"ו עם קבלת נתוני הציוד. | Y19: חסם לטיפול מנהל מגזר תכנון
B20: WBD-120 | C20: תפוח- הצבת תחמ"ש ניידת | D20: ניידת | E20: אוקון שמעון | G20: 46112 | H20: 46052 | J20: קבלת היתר | K20: ="WBS: " & B20 & CHAR(10) & "שם פרויקט: " & C20 & CHAR(10) & "מנה״פ: " & E20 & CHAR(10) & "יעד תכנית פיתוח: " & TEXT(G20,"dd/mm/yyyy") & CHAR(10) & "יעד מסתמן: " & TEXT(H20,"dd/mm/yyyy") -> WBS: WBD-120 שם פרויקט: תפוח- הצבת תחמ"ש ניידת מנה״פ: אוקון שמעון יעד תכנית פיתוח: 31/03/2026 יעד מסתמן: 30/01/2026 | M20: סיור עם כל הגורמים המעורבים בפרויקט בתחילת פברואר | N20: סיור עם כל הגורמים המעורבים בפרויקט בתחילת פברואר | O20: סיור עם כל הגורמים המעורבים בפרויקט בתחילת פברואר | P20: בוצע סיור עם גורמי תכנון ב 4.2, התקבלה דרישה מהקמ"ט למצוא מיקום חלופי | Q20: בוצע סיור עם גורמי תכנון ב 4.2, התקבלה דרישה מהקמ"ט למצוא מיקום חלופי | R20: בוצע סיור עם גורמי תכנון ב 4.2, התקבלה דרישה מהקמ"ט למצוא מיקום חלופי | S20: עדיין לא התקבלה תשובה ממנהל נכסים לגבי מיקום אלטרנטיבי | T20: עדיין לא התקבלה תשובה ממנהל נכסים לגבי מיקום אלטרנטיבי | U20: עדיין לא התקבלה תשובה ממנהל נכסים לגבי מיקום אלטרנטיבי | V20: עדיין לא התקבלה תשובה ממנהל נכסים לגבי מיקום אלטרנטיבי | W20: נבדקת חלופה מספר 2 למיקום חלופי לניידת | Y20: חסם לטיפול מנהל אגף
A21: כן | B21: WBD-090 | C21: ענתות-הצבת תחמ"ש ניידת 30 מגוו"א | D21: ניידת | E21: אוקון שמעון | G21: 46172 | H21: 46203 | J21: קבלת היתר | K21: ="WBS: " & B21 & CHAR(10) & "שם פרויקט: " & C21 & CHAR(10) & "מנה״פ: " & E21 & CHAR(10) & "יעד תכנית פיתוח: " & TEXT(G21,"dd/mm/yyyy") & CHAR(10) & "יעד מסתמן: " & TEXT(H21,"dd/mm/yyyy") -> WBS: WBD-090 שם פרויקט: ענתות-הצבת תחמ"ש ניידת 30 מגוו"א מנה״פ: אוקון שמעון יעד תכנית פיתוח: 30/05/2026 יעד מסתמן: 30/06/2026 | M21: תקוע באישורי קמ"ט ולא ניתן עד אז גם להוציא הזמנה לקבלן האזרחי שמתוכנן למכבים ומסוגל לבצע גם בענתות | N21: עדכון 14.1: תקוע באישורי קמ"ט ולא ניתן עד אז גם להוציא הזמנה לקבלן האזרחי שמתוכנן למכבים ומסוגל לבצע גם בענתות עדכון 20.1: הועברה תוכנית העמדה כולל פיתוח שטח שביל כניסה לאתר ליוסי סיטרון להמשך טיפול לאישור מול קמ"ט | O21: עדכון 14.1: תקוע באישורי קמ"ט ולא ניתן עד אז גם להוציא הזמנה לקבלן האזרחי שמתוכנן למכבים ומסוגל לבצע גם בענתות עדכון 20.1: הועברה תוכנית העמדה כולל פיתוח שטח שביל כניסה לאתר ליוסי סיטרון להמשך טיפול לאישור מול קמ"ט | P21: עדכון 14.1: תקוע באישורי קמ"ט ולא ניתן עד אז גם להוציא הזמנה לקבלן האזרחי שמתוכנן למכבים ומסוגל לבצע גם בענתות עדכון 20.1: הועברה תוכנית העמדה כולל פיתוח שטח שביל כניסה לאתר ליוסי סיטרון להמשך טיפול לאישור מול קמ"ט | Q21: תקוע באישורי קמ"ט ולא ניתן עד אז גם להוציא הזמנה לקבלן האזרחי שמתוכנן למכבים ומסוגל לבצע גם בענתות הועברה תוכנית העמדה כולל פיתוח שטח שביל כניסה לאתר ליוסי סיטרון להמשך טיפול לאישור מול קמ"ט | R21: תקוע באישורי קמ"ט ולא ניתן עד אז גם להוציא הזמנה לקבלן האזרחי שמתוכנן למכבים ומסוגל לבצע גם בענתות הועברה תוכנית העמדה כולל פיתוח שטח שביל כניסה לאתר ליוסי סיטרון להמשך טיפול לאישור מול קמ"ט | S21: תקוע באישורי קמ"ט ולא ניתן עד אז גם להוציא הזמנה לקבלן האזרחי שמתוכנן למכבים ומסוגל לבצע גם בענתות הועברה תוכנית העמדה כולל פיתוח שטח שביל כניסה לאתר ליוסי סיטרון להמשך טיפול לאישור מול קמ"ט | T21: תקוע באישורי קמ"ט ולא ניתן עד אז גם להוציא הזמנה לקבלן האזרחי שמתוכנן למכבים ומסוגל לבצע גם בענתות הועברה תוכנית העמדה כולל פיתוח שטח שביל כניסה לאתר ליוסי סיטרון להמשך טיפול לאישור מול קמ"ט | U21: תקוע באישורי קמ"ט ולא ניתן עד אז גם להוציא הזמנה לקבלן האזרחי שמתוכנן למכבים ומסוגל לבצע גם בענתות הועברה תוכנית העמדה כולל פיתוח שטח שביל כניסה לאתר ליוסי סיטרון להמשך טיפול לאישור מול קמ"ט | V21: תקוע באישורי קמ"ט ולא ניתן עד אז גם להוציא הזמנה לקבלן האזרחי שמתוכנן למכבים ומסוגל לבצע גם בענתות הועברה תוכנית העמדה כולל פיתוח שטח שביל כניסה לאתר ליוסי סיטרון להמשך טיפול לאישור מול קמ"ט | W21: תקוע באישורי קמ"ט ולא ניתן עד אז גם להוציא הזמנה לקבלן האזרחי שמתוכנן למכבים ומסוגל לבצע גם בענתות הועברה תוכנית העמדה כולל פיתוח שטח שביל כניסה לאתר ליוסי סיטרון להמשך טיפול לאישור מול קמ"ט | Y21: חסם לטיפול מנהל אגף
A22: כן | B22: WBD-121 | C22: עמנואל 2 ניידת- הצבת תחמ"ש ניידת | D22: ניידת | E22: אוקון שמעון | G22: 46203 | H22: 46052 | K22: ="WBS: " & B22 & CHAR(10) & "שם פרויקט: " & C22 & CHAR(10) & "מנה״פ: " & E22 & CHAR(10) & "יעד תכנית פיתוח: " & TEXT(G22,"dd/mm/yyyy") & CHAR(10) & "יעד מסתמן: " & TEXT(H22,"dd/mm/yyyy") -> WBS: WBD-121 שם פרויקט: עמנואל 2 ניידת- הצבת תחמ"ש ניידת מנה״פ: אוקון שמעון יעד תכנית פיתוח: 30/06/2026 יעד מסתמן: 30/01/2026 | M22: מתוכננת הובלה כפולה בליל ה 29.1 מאלעד לעמנואל ומעמנואל למודיעין הכנסת ניידת ב29.1 | N22: מתוכננת הובלה כפולה בליל ה 29.1 מאלעד לעמנואל ומעמנואל למודיעין הכנסת ניידת ב29.1 | O22: מתוכננת הובלה כפולה בליל ה 29.1 מאלעד לעמנואל ומעמנואל למודיעין הכנסת ניידת ב29.1 ניידת באלעד 2 פורקה, עברה טסט ומוכנה להובלה ב 26.1 תובלה הגיעו לעמנואל להכין את הנגרר לפינוי | P22: הניידת שהייתה מיועדת לעמנואל מאלעד 2 הוקצתה לירושלים ד, בהחלטת הנהלה עקב תקלה שהייתה בניידת בירושלים. בלילה 29.1 פונה הנגרר התקול מעמנואל למודיעין יש לקבל הקצאת ניידת עבור עמנואל | Q22: הניידת שהייתה מיועדת לעמנואל מאלעד 2 הוקצתה לירושלים ד, בהחלטת הנהלה עקב תקלה שהייתה בניידת בירושלים. בלילה 29.1 פונה הנגרר התקול מעמנואל למודיעין יש לקבל הקצאת ניידת עבור עמנואל | R22: הניידת שהייתה מיועדת לעמנואל מאלעד 2 הוקצתה לירושלים ד, בהחלטת הנהלה עקב תקלה שהייתה בניידת בירושלים. בלילה 29.1 פונה הנגרר התקול מעמנואל למודיעין יש לקבל הקצאת ניידת עבור עמנואל | S22: אין הקצאת ניידת - HOLD | T22: אין הקצאת ניידת - HOLD | U22: אין הקצאת ניידת - HOLD | V22: אין הקצאת ניידת - HOLD | W22: אין הקצאת ניידת - HOLD | Y22: חסם לטיפול מנהל אגף
B23: WBD-096 | C23: א.ת. מכבים- הצבת תחמ"ש ניידת 161/33 ק"ו, 20 מגוו"א | D23: ניידת | E23: אוקון שמעון | G23: 46599 | H23: 46259 | J23: קבלת היתר | K23: ="WBS: " & B23 & CHAR(10) & "שם פרויקט: " & C23 & CHAR(10) & "מנה״פ: " & E23 & CHAR(10) & "יעד תכנית פיתוח: " & TEXT(G23,"dd/mm/yyyy") & CHAR(10) & "יעד מסתמן: " & TEXT(H23,"dd/mm/yyyy") -> WBS: WBD-096 שם פרויקט: א.ת. מכבים- הצבת תחמ"ש ניידת 161/33 ק"ו, 20 מגוו"א מנה״פ: אוקון שמעון יעד תכנית פיתוח: 31/07/2027 יעד מסתמן: 25/08/2026 | M23: תקוע באישורי קמ"ט ולא ניתן עד אז גם להוציא הזמנה לקבלן האזרחי שבאתר | N23: עדכון 14.1: תקוע באישורי קמ"ט ולא ניתן עד אז גם להוציא הזמנה לקבלן האזרחי שבאתר עדכון 20.1: התקבלה הדעה מסעיד ביום 18.1-" יש התכנות רעיונית ונדרש להגיש תכנית מפורטת" - הנושא בבירור של יוסי סיטרון מול סעיד להבין מה נדרש להגיש (כבר הוגשה תכנית העמדה כפי שביקש) | O23: עדכון 14.1: תקוע באישורי קמ"ט ולא ניתן עד אז גם להוציא הזמנה לקבלן האזרחי שבאתר עדכון 20.1: התקבלה הדעה מסעיד ביום 18.1- יש התכנות רעיונית ונדרש להגיש תכנית מפורטת - הנושא בבירור של יוסי סיטרון מול סעיד להבין מה נדרש להגיש (כבר הוגשה תכנית העמדה כפי שביקש) | P23: עדכון 5.2: התקבל אישור קמ"ט אנרגיה לביצוע והקמת האתר לניידת מכבים. | Q23: התקבל אישור קמ"ט אנרגיה לביצוע והקמת האתר לניידת מכבים. | R23: התקבל אישור קמ"ט אנרגיה לביצוע והקמת האתר לניידת מכבים. | S23: בשלב מו"מ עם הקבלן | T23: בשלב מו"מ עם הקבלן | U23: בשלב מו"מ עם הקבלן | V23: בשלב מו"מ עם הקבלן | W23: בשלב הכנת הסכם רכש מול הקבלן
B24: WBD-123 | C24: א.ת. מכבים- הצבת תחמ"ש ניידת 161/24 ק"ו, 20 מגוו"א | D24: ניידת | E24: אוקון שמעון | G24: 46142 | H24: 46244 | J24: קבלת היתר | K24: ="WBS: " & B24 & CHAR(10) & "שם פרויקט: " & C24 & CHAR(10) & "מנה״פ: " & E24 & CHAR(10) & "יעד תכנית פיתוח: " & TEXT(G24,"dd/mm/yyyy") & CHAR(10) & "יעד מסתמן: " & TEXT(H24,"dd/mm/yyyy") -> WBS: WBD-123 שם פרויקט: א.ת. מכבים- הצבת תחמ"ש ניידת 161/24 ק"ו, 20 מגוו"א מנה״פ: אוקון שמעון יעד תכנית פיתוח: 30/04/2026 יעד מסתמן: 10/08/2026 | M24: תקוע באישורי קמ"ט ולא ניתן עד אז גם להוציא הזמנה לקבלן האזרחי שבאתר | N24: עדכון 14.1: תקוע באישורי קמ"ט ולא ניתן עד אז גם להוציא הזמנה לקבלן האזרחי שבאתר עדכון 20.1: התקבלה הדעה מסעיד ביום 18.1-" יש התכנות רעיונית ונדרש להגיש תכנית מפורטת" - הנושא בבירור של יוסי סיטרון מול סעיד להבין מה נדרש להגיש (כבר הוגשה תכנית העמדה כפי שביקש) | O24: עדכון 14.1: תקוע באישורי קמ"ט ולא ניתן עד אז גם להוציא הזמנה לקבלן האזרחי שבאתר עדכון 20.1: התקבלה הדעה מסעיד ביום 18.1-" יש התכנות רעיונית ונדרש להגיש תכנית מפורטת" - הנושא בבירור של יוסי סיטרון מול סעיד להבין מה נדרש להגיש (כבר הוגשה תכנית העמדה כפי שביקש) | P24: עדכון 5.2: התקבל אישור קמ"ט אנרגיה לביצוע והקמת האתר לניידת מכבים. | Q24: עדכון 5.2: התקבל אישור קמ"ט אנרגיה לביצוע והקמת האתר לניידת מכבים. | R24: התקבל אישור קמ"ט אנרגיה לביצוע והקמת האתר לניידת מכבים. | S24: בשלב מו"מ עם הקבלן | T24: בשלב מו"מ עם הקבלן | U24: בשלב מו"מ עם הקבלן | V24: בשלב מו"מ עם הקבלן | W24: בשלב הכנת הסכם רכש מול הקבלן
B25: WBE-288 | C25: שפרינצק-התקנת שנאי רביעי מס' 524, 50 מגוו"א וסוללות קבלים | D25: הרחבה | E25: ארליך-בקיש, רחלי | F25: רחאנה ענבל עינב | G25: 47118 | H25: טרם נקבע | J25: הקפאת תכולה | K25: ="WBS: " & B25 & CHAR(10) & "שם פרויקט: " & C25 & CHAR(10) & "מנה״פ: " & E25 & CHAR(10) & "יעד תכנית פיתוח: " & TEXT(G25,"dd/mm/yyyy") & CHAR(10) & "יעד מסתמן: " & TEXT(H25,"dd/mm/yyyy") -> WBS: WBE-288 שם פרויקט: שפרינצק-התקנת שנאי רביעי מס' 524, 50 מגוו"א וסוללות קבלים מנה״פ: ארליך-בקיש, רחלי יעד תכנית פיתוח: 31/12/2028 יעד מסתמן: טרם נקבע | S25: הוקדם מתוכנית הפיתוח מ 12/28 ל 06/27 , לא נעשה בתיאום עם חטיבת הפרויקטים, מסתמן שלא מסתנכרן עם הפרויקטים האחרים בתחנה. נדרשת פגישה עם כל בעלי העניין לניתוח כלל האשכול - באחריות מנה"פ. | T25: התקבל שינו מהתבונה - סיום ת.פ הוחזר ל 12/28. נדרשת פגישה עם כל בעלי העניין לניתוח כלל האשכול - באחריות מנה"פ. נדרש לקדם הזמת תכנון להיתר | U25: התקבל שינו מהתבונה - סיום ת.פ הוחזר ל 12/28. נדרשת פגישה עם כל בעלי העניין לניתוח כלל האשכול - באחריות מנה"פ. | V25: התקבל שינו מהתבונה - סיום ת.פ הוחזר ל 12/28. נדרשת פגישה עם כל בעלי העניין לניתוח כלל האשכול - באחריות מנה"פ. | W25: התקבל שינו מהתבונה - סיום ת.פ הוחזר ל 12/28. נדרשת פגישה עם כל בעלי העניין לניתוח כלל האשכול - באחריות מנה"פ. תתואם פגישה לקראת סוף אפריל | Y25: חסם לטיפול מנהל מגזר תכנון
B26: WBE-290 | C26: איילון- התקנת שנאי רביעי 75 מגוו"א 161/24 ק"ו | D26: הרחבה | E26: אוברקוביץ, ענת | F26: סויסה ענת | G26: 46387 | H26: 46386 | J26: תכנון | K26: ="WBS: " & B26 & CHAR(10) & "שם פרויקט: " & C26 & CHAR(10) & "מנה״פ: " & E26 & CHAR(10) & "יעד תכנית פיתוח: " & TEXT(G26,"dd/mm/yyyy") & CHAR(10) & "יעד מסתמן: " & TEXT(H26,"dd/mm/yyyy") -> WBS: WBE-290 שם פרויקט: איילון- התקנת שנאי רביעי 75 מגוו"א 161/24 ק"ו מנה״פ: אוברקוביץ, ענת יעד תכנית פיתוח: 31/12/2026 יעד מסתמן: 30/12/2026 | S26: פרויקט מתפרץ. בוצע סיור מקדים מול תכנון אלקטרומכני, מחלקת ציוד וכיבוי אש. נקבעה ישיבת התנעת פרויקט ל 25.02. | T26: בוצעה ישיבת התנעה לפרויקט. הוצאת הזמנה לתכנון אזרחי 03/26. כתב כמויות 06/26. בבדיקה מול רת"ק תוואי כבל 161 בין השנאי למסדר. | U26: בוצעה ישיבת התנעה לפרויקט. הוצאת הזמנה לתכנון אזרחי 03/26. כתב כמויות 06/26. בבדיקה מול רת"ק תוואי כבל 161 בין השנאי למסדר. | V26: הזמנה לתכנון אזרחי הופצה ב 16/3/26. בבדיקה מול רת"ק תוואי כבל 161 בין השנאי למסדר. | W26: הזמנה לתכנון אזרחי הופצה ב 16/3/26. בבדיקה מול רת"ק תוואי כבל 161 בין השנאי למסדר. תואמה פגישה עם צמ"ן לבחינת השטח לטובת העברת השנאי משטח 6. | X26: עמידה בלו"ז | Y26: חסם לטיפול מנהל מגזר תכנון
B27: WBD-128 | C27: תימורים- תכנון הצבת 2 תחמ"ש ניידות,30 מגוו"א כ"א | D27: ניידת | E27: אלטחן, קובי | F27: קיעביץ יוסף | G27: 46203 | H27: 46356 | J27: הקפאת תצורה | K27: ="WBS: " & B27 & CHAR(10) & "שם פרויקט: " & C27 & CHAR(10) & "מנה״פ: " & E27 & CHAR(10) & "יעד תכנית פיתוח: " & TEXT(G27,"dd/mm/yyyy") & CHAR(10) & "יעד מסתמן: " & TEXT(H27,"dd/mm/yyyy") -> WBS: WBD-128 שם פרויקט: תימורים- תכנון הצבת 2 תחמ"ש ניידות,30 מגוו"א כ"א מנה״פ: אלטחן, קובי יעד תכנית פיתוח: 30/06/2026 יעד מסתמן: 30/11/2026 | V27: בדיונים על סגירת תוכנית העמדה של הניידות. נקבעה ישיבת הקפאת תצורה לתאריך 29.3.26. נבחנת אפשרות להצבת הניידות מכוח צו שר במקום הליך היתר | W27: בדיונים על סגירת תוכנית העמדה של הניידות. נקבעה ישיבת הקפאת תצורה לתאריך 29.3.26. נבחנת אפשרות להצבת הניידות מכוח צו שר במקום הליך היתר | X27: משך הטיפול בהיתר עלול לקחת זמן רב אשר מייתר את הצורך בהצבת ניידות | Y27: חסם לטיפול מנהל אגף
B28: WBC-075 | C28: תימורים-הקמת תחמ"ש חיצונית 161/24 ק"ו | D28: הקמה | E28: אלטחן, קובי | F28: קיעביץ יוסף | G28: 46356 | H28: 46598 | J28: קבלת היתר | K28: ="WBS: " & B28 & CHAR(10) & "שם פרויקט: " & C28 & CHAR(10) & "מנה״פ: " & E28 & CHAR(10) & "יעד תכנית פיתוח: " & TEXT(G28,"dd/mm/yyyy") & CHAR(10) & "יעד מסתמן: " & TEXT(H28,"dd/mm/yyyy") -> WBS: WBC-075 שם פרויקט: תימורים-הקמת תחמ"ש חיצונית 161/24 ק"ו מנה״פ: אלטחן, קובי יעד תכנית פיתוח: 30/11/2026 יעד מסתמן: 30/07/2027 | M28: השבוע יצאה הזמנה של מועצה אזורית באר טוביה למתכנן קו הסניקה - משך התכנון - כחודש. התקבלו הערות לתיקון טרם דיון הועדה בהיתר הבנייה - התכנון עובד על תיקונם. עקב עיכוב בהגשת בקשה להיתר צפי לקבלת היתר 05/2026, חריגה מיעד ת.פ 11/26. | N28: הבקשה להיתר המתוקנת הוגשה שוב בתאריך 19.1.26 | O28: ממתינים לדיון ועדה. במקביל מקדמים את פרויקט הניידות | P28: ממתינים לדיון ועדה. במקביל מקדמים את פרויקט הניידות | Q28: הבקשה שוב חזרה עם הערות לתיקון. עובדים על תיקונם והבקשה תוגש שוב בשבוע הבא | R28: הבקשה שוב חזרה עם הערות לתיקון. עובדים על תיקונם והבקשה תוגש שוב עד סוף השבוע | S28: הבקשה להיתר הוגשה שוב, ממתינים לדיון ועדה. השבוע צפוי להסתיים התכנון של הקו סניקה | T28: הבקשה שוב נדחתה וניתנו הערות לתיקון. ביום חמישי צפויה להתקיים פגישה עם מהנדסת העיר להבין מה הבעיה (בכפוף למצב הביטחוני) | U28: התקיימה פגישה עם מח' הנדסה של העירייה ועברנו יחד על הערות שניתנו - הערות תוקנו והבקשה הוגשה שוב. | V28: ממתינים לקבלת תכנון חיצוני להעתקת קו הסניקה. הבקשה עברה ועדה והתקבלו תנאי התכן. שטח התארגנות סוכם עם מהנדסת העיר והועבר לטיפול מנר"א מול גזברות העירייה | W28: ממתינים לקבלת תכנון חיצוני להעתקת קו הסניקה. הבקשה עברה ועדה והתקבלו תנאי התכן. שטח התארגנות סוכם עם מהנדסת העיר והועבר לטיפול מנר"א מול גזברות העירייה | X28: קו הסניקה הקיים בשטח מהווה חסם לעלייה לקרקע.
